Workbook

Sheet Hướng dẫn
A1: HƯỚNG DẪN NHẬP LIỆU NHANH
A2: Nguồn nhập duy nhất | B2: Trung tâm nhập liệu | G2: Cập nhật | H2: =TODAY() -> 46245
A4: 5 QUY TẮC QUAN TRỌNG
A5: 1 | B5: Tìm đúng công việc cha trước khi thêm việc con.
A6: 2 | B6: Điền đủ ô màu vàng; nhập đủ thì màu vàng tự mất.
A7: 3 | B7: Chỉ nhập % tại công việc con thấp nhất.
A8: 4 | B8: Việc định kỳ phải có Loại lịch, Chu kỳ và Nhật ký.
A9: 5 | B9: Không sửa ô công thức; thêm dòng bằng cách sao chép dòng mẫu gần nhất.
A11: QUAN HỆ CÁC LỚP
A12: L3 | B12: Công việc chính — không cần mã cha.
A13: L4 | B13: Chọn mã cha L3.
A14: L5 | B14: Chọn mã cha L4.
A15: L6 | B15: Chọn mã cha L5; đây thường là lớp nhập tác nghiệp chi tiết.
A17: PHẦN TRĂM HOÀN THÀNH
A18: Việc con thấp nhất | B18: Nhập mức thực tế: 0% chưa làm, 1–99% đang làm, 100% hoàn thành.
A19: Công việc cha có con | B19: Không nhập thủ công; hệ thống lấy trung bình % các công việc con hợp lệ.
A20: Khi hoàn thành | B20: Nhập 100%, trạng thái Hoàn thành, ngày thực tế và Link kết quả.
A22: NGUYÊN TẮC NGÀY CHA – CON
A23: Việc thường | B23: Ngày hiển thị cha giữ kế hoạch gốc; chỉ mở rộng nếu con bắt đầu sớm hơn hoặc kết thúc muộn hơn.
A24: Việc phát sinh | B24: Nếu có con: ngày cha = ngày bắt đầu sớm nhất và ngày kết thúc muộn nhất từ con; nếu chưa có con: để trống.
A25: Không có con | B25: Việc thường dùng ngày nhập tại cha; việc phát sinh cấp thấp nhất thì nhập ngày trực tiếp tại chính việc đó.
A26: Cảnh báo | B26: Khi con vượt khung kế hoạch gốc, hệ thống cảnh báo nhưng không tự sửa ngày gốc ở Trung tâm nhập liệu.
A27: Phân biệt ngày | B27: Ngày kế hoạch gốc nằm tại Trung tâm nhập liệu; ngày hiển thị nằm trên các tab L3/L4/L5 và Bản đồ công việc.
A28: CÔNG VIỆC ĐỊNH KỲ
A29: Loại lịch | B29: Chọn Định kỳ.
A30: Chu kỳ | B30: Chọn nhịp thực hiện phù hợp.
A31: Mỗi lần thực hiện | B31: Ghi một dòng trong Nhật ký thực hiện tại Trung tâm nhập liệu.
A33: NHẬN DIỆN MÀU
A34: Vàng | B34: Thiếu dữ liệu bắt buộc — cần nhập.
A35: Đỏ | B35: Tìm cha hoặc cảnh báo cần xử lý.
A36: Xám | B36: Thông tin phụ hoặc trường kỹ thuật.

Sheet Trung tâm nhập liệu
A1: TRUNG TÂM NHẬP LIỆU CÔNG VIỆC
B62: BẢNG MASTER — TRUNG TÂM NHẬP LIỆU
A63: STT | B63: Mã công việc | C63: Cấp | D63: Mã cha | E63: Năm | F63: Tên công việc | G63: Kết quả đầu ra | H63: Giá trị mang lại | I63: Đơn vị phụ trách | J63: Người Lead | K63: Người thực hiện | L63: Trạng thái | M63: Mức độ ưu tiên | N63: Phần trăm hoàn thành | O63: Loại lịch | P63: Chu kỳ | Q63: Ngày kết thúc | R63: Ngày bắt đầu | S63: Ngày rà soát | T63: Khối lượng nhập (giờ, mã thấp nhất) | U63: Khối lượng quản trị (giờ) | V63: Đơn vị phân bổ | W63: Phân bổ (giờ/kỳ) | X63: Ngày HT thực tế | Y63: Link kết quả | Z63: Có mã con?
A65: LỚP 3 — CÔNG VIỆC CHÍNH (L3) | I65: R&D
F66: Cấp đầu tiên — nhập công việc tại các dòng bên dưới; không cần mã cha. | I66: R&D
A67: =IF(OR($B67="",$C67=""),"",COUNTIFS($C$67:$C67,$C67,$B$67:$B67,"<>")) -> 1 | B67: HHL3CT01 | C67: L3 | E67: 2026 | F67: Xây dựng bộ chiến lược công ty tầm nhìn 2030 | G67: Được TGĐ phê duyệt | I67: Công ty | J67: GĐ BOC | K67: GĐ BOC | L67: Đã lên lịch | M67: P1 | N67: =IF(B67="","",IF(OR(L67="Chưa lên lịch",L67="Đã lên lịch",L67="Hủy"),"",IF(COUNTIFS($D$67:$D$212,B67,$L$67:$L$212,"<>",$L$67:$L$212,"<>Hủy",$L$67:$L$212,"<>Chưa lên lịch",$L$67:$L$212,"<>Đã lên lịch")>0,AVERAGEIFS($N$67:$N$212,$D$67:$D$212,B67,$L$67:$L$212,"<>",$L$67:$L$212,"<>Hủy",$L$67:$L$212,"<>Chưa lên lịch",$L$67:$L$212,"<>Đã lên lịch"),IF(L67="Hoàn thành",1,0)))) | O67: Có thời hạn | P67: Năm | Q67: 46420 | R67: 46341 | T67: 200 | U67: =IF(B67="","",IF(Z67="Có",'Lớp 3 - Công việc chính'!AE14,T67)) -> 200 | V67: Tuần | W67: 3 | Z67: =IF(B67="","",IF(COUNTIF($D$67:$D$212,B67)>0,"Có","Không")) -> Không
A68: =IF(OR($B68="",$C68=""),"",COUNTIFS($C$67:$C68,$C68,$B$67:$B68,"<>")) -> 2 | B68: HHL3CT02 | C68: L3 | E68: 2026 | F68: Xây dựng bộ VHDN | G68: Được TGĐ phê duyệt | I68: Công ty | J68: GĐ BOC | K68: GĐ BOC | L68: Đã lên lịch | M68: P2 | N68: =IF(B68="","",IF(OR(L68="Chưa lên lịch",L68="Đã lên lịch",L68="Hủy"),"",IF(COUNTIFS($D$67:$D$212,B68,$L$67:$L$212,"<>",$L$67:$L$212,"<>Hủy",$L$67:$L$212,"<>Chưa lên lịch",$L$67:$L$212,"<>Đã lên lịch")>0,AVERAGEIFS($N$67:$N$212,$D$67:$D$212,B68,$L$67:$L$212,"<>",$L$67:$L$212,"<>Hủy",$L$67:$L$212,"<>Chưa lên lịch",$L$67:$L$212,"<>Đã lên lịch"),IF(L68="Hoàn thành",1,0)))) | O68: Có thời hạn | P68: Năm | Q68: 46420 | R68: 46341 | T68: 100 | U68: =IF(B68="","",IF(Z68="Có",'Lớp 3 - Công việc chính'!AE15,T68)) -> 100 | V68: Tuần | W68: 3 | Z68: =IF(B68="","",IF(COUNTIF($D$67:$D$212,B68)>0,"Có","Không")) -> Không
A69: =IF(OR($B69="",$C69=""),"",COUNTIFS($C$67:$C69,$C69,$B$67:$B69,"<>")) -> 3 | B69: HHL3CT03 | C69: L3 | E69: 2026 | F69: KHKD 2027& HT lập KH theo tham số KD (bán tự động) | G69: Được TĐ phê duyệt | I69: Dữ liệu điều hành | J69: GĐ BOC | K69: Em Đại | L69: Đang thực hiện | M69: P1 | N69: =IF(B69="","",IF(OR(L69="Chưa lên lịch",L69="Đã lên lịch",L69="Hủy"),"",IF(COUNTIFS($D$67:$D$212,B69,$L$67:$L$212,"<>",$L$67:$L$212,"<>Hủy",$L$67:$L$212,"<>Chưa lên lịch",$L$67:$L$212,"<>Đã lên lịch")>0,AVERAGEIFS($N$67:$N$212,$D$67:$D$212,B69,$L$67:$L$212,"<>",$L$67:$L$212,"<>Hủy",$L$67:$L$212,"<>Chưa lên lịch",$L$67:$L$212,"<>Đã lên lịch"),IF(L69="Hoàn thành",1,0)))) -> 0.069642857 | O69: Có thời hạn | Q69: 46337 | R69: 46237 | T69: 560 | U69: =IF(B69="","",IF(Z69="Có",'Lớp 3 - Công việc chính'!AE16,T69)) -> 620 | V69: Tuần | W69: 3 | Z69: =IF(B69="","",IF(COUNTIF($D$67:$D$212,B69)>0,"Có","Không")) -> Có
A70: =IF(OR($B70="",$C70=""),"",COUNTIFS($C$67:$C70,$C70,$B$67:$B70,"<>")) -> 4 | B70: HHL3RD01 | C70: L3 | E70: 2026 | F70: KH sản phẩm 2027-2030 | G70: Được TGĐ phê duyệt | I70: R&D | J70: GĐ BOC | K70: Ms Trang | L70: Đang thực hiện | M70: P1 | N70: =IF(B70="","",IF(OR(L70="Chưa lên lịch",L70="Đã lên lịch",L70="Hủy"),"",IF(COUNTIFS($D$67:$D$212,B70,$L$67:$L$212,"<>",$L$67:$L$212,"<>Hủy",$L$67:$L$212,"<>Chưa lên lịch",$L$67:$L$212,"<>Đã lên lịch")>0,AVERAGEIFS($N$67:$N$212,$D$67:$D$212,B70,$L$67:$L$212,"<>",$L$67:$L$212,"<>Hủy",$L$67:$L$212,"<>Chưa lên lịch",$L$67:$L$212,"<>Đã lên lịch"),IF(L70="Hoàn thành",1,0)))) -> 0 | O70: Có thời hạn | Q70: 46305 | R70: 46223 | T70: 224 | U70: =IF(B70="","",IF(Z70="Có",'Lớp 3 - Công việc chính'!AE17,T70)) | Z70: =IF(B70="","",IF(COUNTIF($D$67:$D$212,B70)>0,"Có","Không")) -> Có
A71: =IF(OR($B71="",$C71=""),"",COUNTIFS($C$67:$C71,$C71,$B$67:$B71,"<>")) -> 5 | B71: HHL3RD02 | C71: L3 | E71: 2026 | F71: Danh mục SP OEM đề xuất | G71: Được TGĐ phê duyệt | I71: R&D | J71: GĐ BOC | K71: Ms Trang | L71: Đang thực hiện | M71: P2 | N71: =IF(B71="","",IF(OR(L71="Chưa lên lịch",L71="Đã lên lịch",L71="Hủy"),"",IF(COUNTIFS($D$67:$D$212,B71,$L$67:$L$212,"<>",$L$67:$L$212,"<>Hủy",$L$67:$L$212,"<>Chưa lên lịch",$L$67:$L$212,"<>Đã lên lịch")>0,AVERAGEIFS($N$67:$N$212,$D$67:$D$212,B71,$L$67:$L$212,"<>",$L$67:$L$212,"<>Hủy",$L$67:$L$212,"<>Chưa lên lịch",$L$67:$L$212,"<>Đã lên lịch"),IF(L71="Hoàn thành",1,0)))) -> 0 | O71: Có thời hạn | Q71: 46274 | R71: 46223 | T71: 120 | U71: =IF(B71="","",IF(Z71="Có",'Lớp 3 - Công việc chính'!AE18,T71)) -> 120 | Z71: =IF(B71="","",IF(COUNTIF($D$67:$D$212,B71)>0,"Có","Không")) -> Có
A72: =IF(OR($B72="",$C72=""),"",COUNTIFS($C$67:$C72,$C72,$B$67:$B72,"<>")) -> 6 | B72: HHL3RD04 | C72: L3 | E72: 2026 | F72: Xây dựng master file & xác định điểm A | G72: Nhìn được hiện trạng trên BI | I72: R&D | J72: GĐ BOC | K72: Ms Trang | L72: Đang thực hiện | M72: P2 | N72: =IF(B72="","",IF(OR(L72="Chưa lên lịch",L72="Đã lên lịch",L72="Hủy"),"",IF(COUNTIFS($D$67:$D$212,B72,$L$67:$L$212,"<>",$L$67:$L$212,"<>Hủy",$L$67:$L$212,"<>Chưa lên lịch",$L$67:$L$212,"<>Đã lên lịch")>0,AVERAGEIFS($N$67:$N$212,$D$67:$D$212,B72,$L$67:$L$212,"<>",$L$67:$L$212,"<>Hủy",$L$67:$L$212,"<>Chưa lên lịch",$L$67:$L$212,"<>Đã lên lịch"),IF(L72="Hoàn thành",1,0)))) -> 0 | O72: Có thời hạn | Q72: 46368 | R72: 46223 | T72: 160 | U72: =IF(B72="","",IF(Z72="Có",'Lớp 3 - Công việc chính'!AE20,T72)) -> 160 | Z72: =IF(B72="","",IF(COUNTIF($D$67:$D$212,B72)>0,"Có","Không")) -> Không
A73: =IF(OR($B73="",$C73=""),"",COUNTIFS($C$67:$C73,$C73,$B$67:$B73,"<>")) -> 7 | B73: HHL3RD05 | C73: L3 | E73: 2026 | F73: Sự vụ quan trọng phát sinh (Vùng xám) | G73: BC theo CV phát sinh | I73: R&D | J73: GĐ BOC | K73: Ms Trang | L73: Đang thực hiện | M73: P1 | N73: =IF(B73="","",IF(OR(L73="Chưa lên lịch",L73="Đã lên lịch",L73="Hủy"),"",IF(COUNTIFS($D$67:$D$212,B73,$L$67:$L$212,"<>",$L$67:$L$212,"<>Hủy",$L$67:$L$212,"<>Chưa lên lịch",$L$67:$L$212,"<>Đã lên lịch")>0,AVERAGEIFS($N$67:$N$212,$D$67:$D$212,B73,$L$67:$L$212,"<>",$L$67:$L$212,"<>Hủy",$L$67:$L$212,"<>Chưa lên lịch",$L$67:$L$212,"<>Đã lên lịch"),IF(L73="Hoàn thành",1,0)))) -> 0 | O73: Có thời hạn | Q73: 46387 | R73: 46223 | T73: 160 | U73: =IF(B73="","",IF(Z73="Có",'Lớp 3 - Công việc chính'!AE21,T73)) -> 160 | Z73: =IF(B73="","",IF(COUNTIF($D$67:$D$212,B73)>0,"Có","Không")) -> Không
A74: =IF(OR($B74="",$C74=""),"",COUNTIFS($C$67:$C74,$C74,$B$67:$B74,"<>")) -> 8 | B74: HHL3RD06 | C74: L3 | E74: 2026 | F74: XD quy chế đào tạo & Chiến lược đào tạo SP | G74: Hoàn thiện quy chế và khung đào tạo sản phẩm áp dụng thống nhất trong R&D | I74: R&D | J74: GĐ BOC | K74: Ms Trang | L74: Đang thực hiện | M74: P2 | N74: =IF(B74="","",IF(OR(L74="Chưa lên lịch",L74="Đã lên lịch",L74="Hủy"),"",IF(COUNTIFS($D$67:$D$212,B74,$L$67:$L$212,"<>",$L$67:$L$212,"<>Hủy",$L$67:$L$212,"<>Chưa lên lịch",$L$67:$L$212,"<>Đã lên lịch")>0,AVERAGEIFS($N$67:$N$212,$D$67:$D$212,B74,$L$67:$L$212,"<>",$L$67:$L$212,"<>Hủy",$L$67:$L$212,"<>Chưa lên lịch",$L$67:$L$212,"<>Đã lên lịch"),IF(L74="Hoàn thành",1,0)))) -> 0 | O74: Có thời hạn | Q74: 46449 | R74: 46223 | T74: 120 | U74: =IF(B74="","",IF(Z74="Có",'Lớp 3 - Công việc chính'!AE22,T74)) -> 120 | Z74: =IF(B74="","",IF(COUNTIF($D$67:$D$212,B74)>0,"Có","Không")) -> Không
A75: =IF(OR($B75="",$C75=""),"",COUNTIFS($C$67:$C75,$C75,$B$67:$B75,"<>")) -> 9 | B75: HHL3RD07 | C75: L3 | E75: 2026 | F75: XD cấu trúc, khoảng trống NL và kiện toàn bộ máy NS R&D | G75: Xác định mô hình tổ chức, khoảng trống năng lực và phương án kiện toàn nhân sự R&D | I75: R&D | J75: GĐ BOC | K75: Ms Trang | L75: Đang thực hiện | M75: P2 | N75: =IF(B75="","",IF(OR(L75="Chưa lên lịch",L75="Đã lên lịch",L75="Hủy"),"",IF(COUNTIFS($D$67:$D$212,B75,$L$67:$L$212,"<>",$L$67:$L$212,"<>Hủy",$L$67:$L$212,"<>Chưa lên lịch",$L$67:$L$212,"<>Đã lên lịch")>0,AVERAGEIFS($N$67:$N$212,$D$67:$D$212,B75,$L$67:$L$212,"<>",$L$67:$L$212,"<>Hủy",$L$67:$L$212,"<>Chưa lên lịch",$L$67:$L$212,"<>Đã lên lịch"),IF(L75="Hoàn thành",1,0)))) -> 0 | O75: Có thời hạn | Q75: 46449 | R75: 46223 | T75: 160 | U75: =IF(B75="","",IF(Z75="Có",'Lớp 3 - Công việc chính'!AE23,T75)) -> 160 | Z75: =IF(B75="","",IF(COUNTIF($D$67:$D$212,B75)>0,"Có","Không")) -> Không
A76: =IF(OR($B76="",$C76=""),"",COUNTIFS($C$67:$C76,$C76,$B$67:$B76,"<>")) -> 10 | B76: HHL3RD08 | C76: L3 | E76: 2026 | F76: Hoạt động nghiên cứu cơ bản & CĐS ngành VPP | G76: Hình thành nền tảng nghiên cứu và lộ trình chuyển đổi số cho ngành VPP | I76: R&D | J76: GĐ BOC | K76: Ms Trang | L76: Đang thực hiện | M76: P2 | N76: =IF(B76="","",IF(OR(L76="Chưa lên lịch",L76="Đã lên lịch",L76="Hủy"),"",IF(COUNTIFS($D$67:$D$212,B76,$L$67:$L$212,"<>",$L$67:$L$212,"<>Hủy",$L$67:$L$212,"<>Chưa lên lịch",$L$67:$L$212,"<>Đã lên lịch")>0,AVERAGEIFS($N$67:$N$212,$D$67:$D$212,B76,$L$67:$L$212,"<>",$L$67:$L$212,"<>Hủy",$L$67:$L$212,"<>Chưa lên lịch",$L$67:$L$212,"<>Đã lên lịch"),IF(L76="Hoàn thành",1,0)))) -> 0 | O76: Có thời hạn | Q76: 46387 | R76: 46223 | T76: 240 | U76: =IF(B76="","",IF(Z76="Có",'Lớp 3 - Công việc chính'!AE24,T76)) -> 240 | Z76: =IF(B76="","",IF(COUNTIF($D$67:$D$212,B76)>0,"Có","Không")) -> Không
A77: =IF(OR($B77="",$C77=""),"",COUNTIFS($C$67:$C77,$C77,$B$67:$B77,"<>")) -> 11 | B77: HHL3RD09 | C77: L3 | E77: 2026 | F77: XD phương án Market Research & Cơ chế thu thập thông tin TT | G77: Thiết lập phương án nghiên cứu thị trường và cơ chế thu thập, cập nhật thông tin định kỳ | I77: R&D | J77: GĐ BOC | K77: Ms Trang | L77: Đang thực hiện | M77: P2 | N77: =IF(B77="","",IF(OR(L77="Chưa lên lịch",L77="Đã lên lịch",L77="Hủy"),"",IF(COUNTIFS($D$67:$D$212,B77,$L$67:$L$212,"<>",$L$67:$L$212,"<>Hủy",$L$67:$L$212,"<>Chưa lên lịch",$L$67:$L$212,"<>Đã lên lịch")>0,AVERAGEIFS($N$67:$N$212,$D$67:$D$212,B77,$L$67:$L$212,"<>",$L$67:$L$212,"<>Hủy",$L$67:$L$212,"<>Chưa lên lịch",$L$67:$L$212,"<>Đã lên lịch"),IF(L77="Hoàn thành",1,0)))) -> 0 | O77: Có thời hạn | Q77: 46280 | R77: 46223 | T77: 160 | U77: =IF(B77="","",IF(Z77="Có",'Lớp 3 - Công việc chính'!AE25,T77)) -> 160 | Z77: =IF(B77="","",IF(COUNTIF($D$67:$D$212,B77)>0,"Có","Không")) -> Có
A78: =IF(OR($B78="",$C78=""),"",COUNTIFS($C$67:$C78,$C78,$B$67:$B78,"<>")) -> 12 | B78: HHL3RD10 | C78: L3 | E78: 2026 | F78: Việc phát sinh khác chưa có phân loại | G78: Dùng để kiểm soát các CV chi tiết hàng ngày | I78: R&D | J78: GĐ BOC | K78: Ms Trang | L78: Đang thực hiện | M78: P3 | N78: =IF(B78="","",IF(OR(L78="Chưa lên lịch",L78="Đã lên lịch",L78="Hủy"),"",IF(COUNTIFS($D$67:$D$212,B78,$L$67:$L$212,"<>",$L$67:$L$212,"<>Hủy",$L$67:$L$212,"<>Chưa lên lịch",$L$67:$L$212,"<>Đã lên lịch")>0,AVERAGEIFS($N$67:$N$212,$D$67:$D$212,B78,$L$67:$L$212,"<>",$L$67:$L$212,"<>Hủy",$L$67:$L$212,"<>Chưa lên lịch",$L$67:$L$212,"<>Đã lên lịch"),IF(L78="Hoàn thành",1,0)))) -> 0 | O78: Có thời hạn | Q78: 46387 | R78: 46223 | T78: 96 | U78: =IF(B78="","",IF(Z78="Có",'Lớp 3 - Công việc chính'!AE26,T78)) -> 96 | Z78: =IF(B78="","",IF(COUNTIF($D$67:$D$212,B78)>0,"Có","Không")) -> Không
A79: =IF(OR($B79="",$C79=""),"",COUNTIFS($C$67:$C79,$C79,$B$67:$B79,"<>")) -> 13 | B79: HHL3RD11 | C79: L3 | E79: 2026 | F79: Xác định & thông qua Xu hướng TK mới 2027 | G79: Xác định và thống nhất định hướng xu hướng thiết kế mới cho năm 2027 | I79: R&D | J79: GĐ BOC | K79: Ms Trang | L79: Đang thực hiện | M79: P2 | N79: =IF(B79="","",IF(OR(L79="Chưa lên lịch",L79="Đã lên lịch",L79="Hủy"),"",IF(COUNTIFS($D$67:$D$212,B79,$L$67:$L$212,"<>",$L$67:$L$212,"<>Hủy",$L$67:$L$212,"<>Chưa lên lịch",$L$67:$L$212,"<>Đã lên lịch")>0,AVERAGEIFS($N$67:$N$212,$D$67:$D$212,B79,$L$67:$L$212,"<>",$L$67:$L$212,"<>Hủy",$L$67:$L$212,"<>Chưa lên lịch",$L$67:$L$212,"<>Đã lên lịch"),IF(L79="Hoàn thành",1,0)))) -> 0 | O79: Có thời hạn | Q79: 46252 | R79: 46235 | T79: 80 | U79: =IF(B79="","",IF(Z79="Có",'Lớp 3 - Công việc chính'!AE27,T79)) -> 80 | Z79: =IF(B79="","",IF(COUNTIF($D$67:$D$212,B79)>0,"Có","Không")) -> Không
A80: =IF(OR($B80="",$C80=""),"",COUNTIFS($C$67:$C80,$C80,$B$67:$B80,"<>")) -> 14 | B80: HHL3RD12 | C80: L3 | E80: 2026 | F80: Xây dựng quy trình và hệ thống quản trị sản phẩm theo phân loại | G80: Chuẩn hóa cơ chế quản trị vòng đời, danh mục, chất lượng và thông tin sản phẩm | I80: R&D | J80: GĐ BOC | K80: Ms Trang | L80: Đang thực hiện | M80: P2 | N80: =IF(B80="","",IF(OR(L80="Chưa lên lịch",L80="Đã lên lịch",L80="Hủy"),"",IF(COUNTIFS($D$67:$D$212,B80,$L$67:$L$212,"<>",$L$67:$L$212,"<>Hủy",$L$67:$L$212,"<>Chưa lên lịch",$L$67:$L$212,"<>Đã lên lịch")>0,AVERAGEIFS($N$67:$N$212,$D$67:$D$212,B80,$L$67:$L$212,"<>",$L$67:$L$212,"<>Hủy",$L$67:$L$212,"<>Chưa lên lịch",$L$67:$L$212,"<>Đã lên lịch"),IF(L80="Hoàn thành",1,0)))) -> 0 | O80: Có thời hạn | Q80: 46387 | R80: 46223 | T80: 280 | U80: =IF(B80="","",IF(Z80="Có",'Lớp 3 - Công việc chính'!AE28,T80)) -> 280 | Z80: =IF(B80="","",IF(COUNTIF($D$67:$D$212,B80)>0,"Có","Không")) -> Có
A81: =IF(OR($B81="",$C81=""),"",COUNTIFS($C$67:$C81,$C81,$B$67:$B81,"<>")) -> 15 | B81: HHL3DL02 | C81: L3 | E81: 2026 | F81: Số hoá DL quản trị all BOC & all PB | G81: Số hóa dữ liệu quản trị, bảo đảm dữ liệu tập trung và khai thác thống nhất toàn BOC, phòng ban | I81: Dữ liệu điều hành | J81: GĐ BOC | K81: Ms Trang | L81: Chưa bắt đầu | M81: P3 | N81: =IF(B81="","",IF(OR(L81="Chưa lên lịch",L81="Đã lên lịch",L81="Hủy"),"",IF(COUNTIFS($D$67:$D$212,B81,$L$67:$L$212,"<>",$L$67:$L$212,"<>Hủy",$L$67:$L$212,"<>Chưa lên lịch",$L$67:$L$212,"<>Đã lên lịch")>0,AVERAGEIFS($N$67:$N$212,$D$67:$D$212,B81,$L$67:$L$212,"<>",$L$67:$L$212,"<>Hủy",$L$67:$L$212,"<>Chưa lên lịch",$L$67:$L$212,"<>Đã lên lịch"),IF(L81="Hoàn thành",1,0)))) -> 0 | O81: Chưa xếp lịch | T81: 240 | U81: =IF(B81="","",IF(Z81="Có",'Lớp 3 - Công việc chính'!AE30,T81)) -> 240 | Z81: =IF(B81="","",IF(COUNTIF($D$67:$D$212,B81)>0,"Có","Không")) -> Không
A82: =IF(OR($B82="",$C82=""),"",COUNTIFS($C$67:$C82,$C82,$B$67:$B82,"<>")) -> 16 | B82: HHL3DL03 | C82: L3 | E82: 2026 | F82: XDHT ngưỡng điều tiết & cung ứng hàng hoá | G82: Thiết lập hệ thống ngưỡng cảnh báo và điều tiết cung ứng hàng hóa | I82: Dữ liệu điều hành | J82: GĐ BOC | K82: Ms Trang | L82: Chưa bắt đầu | M82: P3 | N82: =IF(B82="","",IF(OR(L82="Chưa lên lịch",L82="Đã lên lịch",L82="Hủy"),"",IF(COUNTIFS($D$67:$D$212,B82,$L$67:$L$212,"<>",$L$67:$L$212,"<>Hủy",$L$67:$L$212,"<>Chưa lên lịch",$L$67:$L$212,"<>Đã lên lịch")>0,AVERAGEIFS($N$67:$N$212,$D$67:$D$212,B82,$L$67:$L$212,"<>",$L$67:$L$212,"<>Hủy",$L$67:$L$212,"<>Chưa lên lịch",$L$67:$L$212,"<>Đã lên lịch"),IF(L82="Hoàn thành",1,0)))) -> 0 | O82: Chưa xếp lịch | T82: 160 | U82: =IF(B82="","",IF(Z82="Có",'Lớp 3 - Công việc chính'!AE31,T82)) -> 160 | Z82: =IF(B82="","",IF(COUNTIF($D$67:$D$212,B82)>0,"Có","Không")) -> Có
A83: =IF(OR($B83="",$C83=""),"",COUNTIFS($C$67:$C83,$C83,$B$67:$B83,"<>")) -> 17 | B83: HHL3DL05 | C83: L3 | E83: 2026 | F83: Phát triển HT BC tự động định kỳ | G83: Xây dựng hệ thống báo cáo định kỳ tự động, giảm thao tác tổng hợp thủ công | I83: Dữ liệu điều hành | J83: GĐ BOC | K83: Ms Trang | L83: Chưa bắt đầu | M83: P1 | N83: =IF(B83="","",IF(OR(L83="Chưa lên lịch",L83="Đã lên lịch",L83="Hủy"),"",IF(COUNTIFS($D$67:$D$212,B83,$L$67:$L$212,"<>",$L$67:$L$212,"<>Hủy",$L$67:$L$212,"<>Chưa lên lịch",$L$67:$L$212,"<>Đã lên lịch")>0,AVERAGEIFS($N$67:$N$212,$D$67:$D$212,B83,$L$67:$L$212,"<>",$L$67:$L$212,"<>Hủy",$L$67:$L$212,"<>Chưa lên lịch",$L$67:$L$212,"<>Đã lên lịch"),IF(L83="Hoàn thành",1,0)))) -> 0 | O83: Có thời hạn | Q83: 46265 | R83: 46244 | T83: 200 | U83: =IF(B83="","",IF(Z83="Có",'Lớp 3 - Công việc chính'!AE33,T83)) -> 200 | Z83: =IF(B83="","",IF(COUNTIF($D$67:$D$212,B83)>0,"Có","Không")) -> Không
A84: =IF(OR($B84="",$C84=""),"",COUNTIFS($C$67:$C84,$C84,$B$67:$B84,"<>")) -> 18 | B84: HHL3DL06 | C84: L3 | E84: 2026 | F84: XDHT quản lý NCC | G84: Thiết lập hệ thống quản lý thông tin, đánh giá và theo dõi nhà cung cấp | I84: Dữ liệu điều hành | J84: GĐ BOC | K84: Ms Trang | L84: Chưa bắt đầu | M84: P2 | N84: =IF(B84="","",IF(OR(L84="Chưa lên lịch",L84="Đã lên lịch",L84="Hủy"),"",IF(COUNTIFS($D$67:$D$212,B84,$L$67:$L$212,"<>",$L$67:$L$212,"<>Hủy",$L$67:$L$212,"<>Chưa lên lịch",$L$67:$L$212,"<>Đã lên lịch")>0,AVERAGEIFS($N$67:$N$212,$D$67:$D$212,B84,$L$67:$L$212,"<>",$L$67:$L$212,"<>Hủy",$L$67:$L$212,"<>Chưa lên lịch",$L$67:$L$212,"<>Đã lên lịch"),IF(L84="Hoàn thành",1,0)))) -> 0 | O84: Có thời hạn | Q84: 46265 | R84: 46235 | T84: 240 | U84: =IF(B84="","",IF(Z84="Có",'Lớp 3 - Công việc chính'!AE34,T84)) -> 240 | Z84: =IF(B84="","",IF(COUNTIF($D$67:$D$212,B84)>0,"Có","Không")) -> Có
A85: =IF(OR($B85="",$C85=""),"",COUNTIFS($C$67:$C85,$C85,$B$67:$B85,"<>")) -> 19 | B85: HHL3DL07 | C85: L3 | E85: 2026 | F85: Truy xuất & xử lý DL phát sinh theo yêu cầu | G85: Đáp ứng kịp thời các yêu cầu truy xuất, xử lý và đối soát dữ liệu phát sinh | I85: Dữ liệu điều hành | J85: GĐ BOC | K85: Em Đại | L85: Chưa bắt đầu | M85: P3 | N85: =IF(B85="","",IF(OR(L85="Chưa lên lịch",L85="Đã lên lịch",L85="Hủy"),"",IF(COUNTIFS($D$67:$D$212,B85,$L$67:$L$212,"<>",$L$67:$L$212,"<>Hủy",$L$67:$L$212,"<>Chưa lên lịch",$L$67:$L$212,"<>Đã lên lịch")>0,AVERAGEIFS($N$67:$N$212,$D$67:$D$212,B85,$L$67:$L$212,"<>",$L$67:$L$212,"<>Hủy",$L$67:$L$212,"<>Chưa lên lịch",$L$67:$L$212,"<>Đã lên lịch"),IF(L85="Hoàn thành",1,0)))) -> 0 | O85: Chưa xếp lịch | T85: 120 | U85: =IF(B85="","",IF(Z85="Có",'Lớp 3 - Công việc chính'!AE35,T85)) -> 120 | Z85: =IF(B85="","",IF(COUNTIF($D$67:$D$212,B85)>0,"Có","Không")) -> Không
A86: =IF(OR($B86="",$C86=""),"",COUNTIFS($C$67:$C86,$C86,$B$67:$B86,"<>")) -> 20 | B86: HHL3DL08 | C86: L3 | E86: 2026 | F86: XDHT xếp hàng lên container phục vụ XK | G86: Triển khai các công việc chuyển đổi số và vận hành hệ thống ngoài danh mục chính | I86: Dữ liệu điều hành | J86: GĐ BOC | K86: Em Đại | L86: Chưa bắt đầu | M86: P3 | N86: =IF(B86="","",IF(OR(L86="Chưa lên lịch",L86="Đã lên lịch",L86="Hủy"),"",IF(COUNTIFS($D$67:$D$212,B86,$L$67:$L$212,"<>",$L$67:$L$212,"<>Hủy",$L$67:$L$212,"<>Chưa lên lịch",$L$67:$L$212,"<>Đã lên lịch")>0,AVERAGEIFS($N$67:$N$212,$D$67:$D$212,B86,$L$67:$L$212,"<>",$L$67:$L$212,"<>Hủy",$L$67:$L$212,"<>Chưa lên lịch",$L$67:$L$212,"<>Đã lên lịch"),IF(L86="Hoàn thành",1,0)))) -> 0 | O86: Có thời hạn | Q86: 46264 | R86: 46223 | T86: 120 | U86: =IF(B86="","",IF(Z86="Có",'Lớp 3 - Công việc chính'!AE36,T86)) -> 120
A87: =IF(OR($B87="",$C87=""),"",COUNTIFS($C$67:$C87,$C87,$B$67:$B87,"<>")) -> 21 | B87: HHL3DL09 | C87: L3 | E87: 2026 | F87: Các CV hỗ trợ khác (cho LĐ & PB khác) | G87: Hỗ trợ lãnh đạo và các phòng ban về dữ liệu, báo cáo và công cụ quản trị | I87: Dữ liệu điều hành | J87: GĐ BOC | K87: Em Đại | L87: Chưa bắt đầu | M87: P1 | N87: =IF(B87="","",IF(OR(L87="Chưa lên lịch",L87="Đã lên lịch",L87="Hủy"),"",IF(COUNTIFS($D$67:$D$212,B87,$L$67:$L$212,"<>",$L$67:$L$212,"<>Hủy",$L$67:$L$212,"<>Chưa lên lịch",$L$67:$L$212,"<>Đã lên lịch")>0,AVERAGEIFS($N$67:$N$212,$D$67:$D$212,B87,$L$67:$L$212,"<>",$L$67:$L$212,"<>Hủy",$L$67:$L$212,"<>Chưa lên lịch",$L$67:$L$212,"<>Đã lên lịch"),IF(L87="Hoàn thành",1,0)))) -> 0 | O87: Chưa xếp lịch | T87: 120 | U87: =IF(B87="","",IF(Z87="Có",'Lớp 3 - Công việc chính'!AE37,T87)) -> 360 | Z87: =IF(B87="","",IF(COUNTIF($D$67:$D$212,B87)>0,"Có","Không")) -> Có
A88: =IF(OR($B88="",$C88=""),"",COUNTIFS($C$67:$C88,$C88,$B$67:$B88,"<>")) -> 22 | B88: HHL3DL10 | C88: L3 | E88: 2026 | F88: Xây dựng hệ thống kiểm soát chiết khấu | I88: Dữ liệu điều hành | J88: GĐ BOC | K88: Em Đại | L88: Đã lên lịch | M88: P3 | N88: =IF(B88="","",IF(OR(L88="Chưa lên lịch",L88="Đã lên lịch",L88="Hủy"),"",IF(COUNTIFS($D$67:$D$212,B88,$L$67:$L$212,"<>",$L$67:$L$212,"<>Hủy",$L$67:$L$212,"<>Chưa lên lịch",$L$67:$L$212,"<>Đã lên lịch")>0,AVERAGEIFS($N$67:$N$212,$D$67:$D$212,B88,$L$67:$L$212,"<>",$L$67:$L$212,"<>Hủy",$L$67:$L$212,"<>Chưa lên lịch",$L$67:$L$212,"<>Đã lên lịch"),IF(L88="Hoàn thành",1,0)))) | O88: Có thời hạn | Q88: 46420 | R88: 46357 | U88: =IF(B88="","",IF(Z88="Có",'Lớp 3 - Công việc chính'!AE38,T88)) | Z88: =IF(B88="","",IF(COUNTIF($D$67:$D$212,B88)>0,"Có","Không")) -> Không
A89: =IF(OR($B89="",$C89=""),"",COUNTIFS($C$67:$C89,$C89,$B$67:$B89,"<>")) -> 23 | B89: HHL3DL11 | C89: L3 | E89: 2026 | F89: Xây dựng hệ thống tính giá & Báo giá xuất khẩu | I89: Dữ liệu điều hành | J89: GĐ BOC | K89: Em Đại | L89: Đã lên lịch | N89: =IF(B89="","",IF(OR(L89="Chưa lên lịch",L89="Đã lên lịch",L89="Hủy"),"",IF(COUNTIFS($D$67:$D$212,B89,$L$67:$L$212,"<>",$L$67:$L$212,"<>Hủy",$L$67:$L$212,"<>Chưa lên lịch",$L$67:$L$212,"<>Đã lên lịch")>0,AVERAGEIFS($N$67:$N$212,$D$67:$D$212,B89,$L$67:$L$212,"<>",$L$67:$L$212,"<>Hủy",$L$67:$L$212,"<>Chưa lên lịch",$L$67:$L$212,"<>Đã lên lịch"),IF(L89="Hoàn thành",1,0)))) | O89: Có thời hạn | Q89: 46388 | R89: 46357 | U89: =IF(B89="","",IF(Z89="Có",'Lớp 3 - Công việc chính'!AE39,T89)) | Z89: =IF(B89="","",IF(COUNTIF($D$67:$D$212,B89)>0,"Có","Không")) -> Không
A90: =IF(OR($B90="",$C90=""),"",COUNTIFS($C$67:$C90,$C90,$B$67:$B90,"<>")) -> 24 | B90: HHL3DL12 | C90: L3 | E90: 2026 | F90: CĐS & AI các hoạt động của BOC | I90: Dữ liệu điều hành | J90: GĐ BOC | K90: Em Đại | L90: Chưa lên lịch | N90: =IF(B90="","",IF(OR(L90="Chưa lên lịch",L90="Đã lên lịch",L90="Hủy"),"",IF(COUNTIFS($D$67:$D$212,B90,$L$67:$L$212,"<>",$L$67:$L$212,"<>Hủy",$L$67:$L$212,"<>Chưa lên lịch",$L$67:$L$212,"<>Đã lên lịch")>0,AVERAGEIFS($N$67:$N$212,$D$67:$D$212,B90,$L$67:$L$212,"<>",$L$67:$L$212,"<>Hủy",$L$67:$L$212,"<>Chưa lên lịch",$L$67:$L$212,"<>Đã lên lịch"),IF(L90="Hoàn thành",1,0)))) | O90: Có thời hạn | U90: =IF(B90="","",IF(Z90="Có",'Lớp 3 - Công việc chính'!AE40,T90)) | Z90: =IF(B90="","",IF(COUNTIF($D$67:$D$212,B90)>0,"Có","Không")) -> Có
A91: 25 | B91: HHL3XK01 | C91: L3 | E91: 2026 | F91: XD & vận hành HT CRM XK | I91: Dữ liệu điều hành | J91: GĐ BOC | M91: P1 | N91: =IF(B91="","",IF(OR(L91="Chưa lên lịch",L91="Đã lên lịch",L91="Hủy"),"",IF(COUNTIFS($D$67:$D$212,B91,$L$67:$L$212,"<>",$L$67:$L$212,"<>Hủy",$L$67:$L$212,"<>Chưa lên lịch",$L$67:$L$212,"<>Đã lên lịch")>0,AVERAGEIFS($N$67:$N$212,$D$67:$D$212,B91,$L$67:$L$212,"<>",$L$67:$L$212,"<>Hủy",$L$67:$L$212,"<>Chưa lên lịch",$L$67:$L$212,"<>Đã lên lịch"),IF(L91="Hoàn thành",1,0)))) -> 0 | O91: Có thời hạn | Q91: 46231 | R91: 46244 | U91: =IF(B91="","",IF(Z91="Có",'Lớp 3 - Công việc chính'!AE72,T91)) | Z91: Không
A92: 26 | B92: HHL3XK02 | C92: L3 | E92: 2026 | F92: XD khung tự quyết định giá cho phòng XK | I92: Dữ liệu điều hành | J92: GĐ BOC | M92: P1 | O92: Có thời hạn | Q92: 46253 | R92: 46244 | Z92: Không
A93: 27 | B93: HHL3XK03 | C93: L3 | E93: 2026 | F93: XD khung tự quyết định giá và HT của hàng SX XK | I93: Dữ liệu điều hành | J93: GĐ BOC | M93: P2 | O93: Có thời hạn | Q93: 46387 | R93: 46244 | Z93: Không
A94: 28 | B94: HHL3XK04 | C94: L3 | E94: 2026 | F94: XD phương án khai thác Lead | I94: Dữ liệu điều hành | J94: GĐ BOC | M94: P2 | Z94: Không
A95: 29 | B95: HHL3XK05 | C95: L3 | E95: 2026 | F95: Sự vụ vùng xám phát sinh (XK) | I95: Dữ liệu điều hành | J95: GĐ BOC | M95: P1 | Z95: Có
A96: 30 | B96: HHL3MKT01 | C96: L3 | E96: 2026 | F96: Lập KH MKT 2027 & tầm nhìn 2030 | I96: MKT | J96: GĐ BOC | M96: P2 | Z96: không
A97: 31 | B97: HHL3MKT02 | C97: L3 | E97: 2026 | F97: XDHT quản trị hoạt động trade & # (BI) | I97: MKT | J97: GĐ BOC | M97: P2 | Q97: 46387 | R97: 46337
A98: 32 | B98: HHL3MKT03 | C98: L3 | E98: 2026 | F98: XDHT quản trị ngân sách MKT (BI) | I98: MKT | J98: GĐ BOC | M98: P2
A99: 33 | B99: HHL3MKT04 | C99: L3 | E99: 2026 | F99: Trình phương án hội nghị khách hàng, NPP toàn quốc 2026 | I99: MKT | J99: GĐ BOC | M99: P1 | Q99: 46254 | R99: 46244
A100: 34 | B100: HHL3KH&CƯ01 | C100: L3 | E100: 2026 | F100: XDHT tính giá | I100: KH & Cung ứng | J100: GĐ BOC | M100: P4
B101: HHL3KH&CƯ02 | C101: L3 | E101: 2026 | F101: Số hóa hoạt động KH vật tư | I101: KH & Cung ứng | J101: GĐ BOC | M101: P4
...

Sheet Bản đồ công việc
A1: CONTROL TOWER CÔNG VIỆC
A2: Một điểm nhìn duy nhất: việc cần can thiệp → tải nguồn lực → nhịp deadline → cây L3–L6. Sheet tự động cập nhật; truy vết từng việc tại cột VỊ TRÍ DỮ LIỆU GỐC. | Q2: NGÔN NGỮ BẢN ĐỒ
Q3: ◆ L3 – Công việc chính
A4: TỔNG NÚT CÔNG VIỆC | B4: =COUNTIF($X$24:$X$700,"<>") -> 113 | D4: ƯU TIÊN P1 | E4: =COUNTIFS($X$24:$X$700,"<>",$AB$24:$AB$700,"P1") -> 35 | G4: ĐÃ QUÁ HẠN | H4: =COUNTIFS($X$24:$X$700,"<>",$AI$24:$AI$700,"🔴*") -> 5 | J4: HẠN TRONG 7 NGÀY | K4: =COUNTIFS($X$24:$X$700,"<>",$AI$24:$AI$700,"🟠*") -> 3 | M4: GIỜ CÒN LẠI | N4: =SUMIFS($AH$24:$AH$700,$X$24:$X$700,"<>") -> #REF! | Q4: ├─ L4 – Danh mục
Q5: ├─ L5 – Nhiệm vụ
A6: TOP 3 VIỆC CẦN CAN THIỆP | Q6: └─ L6 – Chi tiết cuối
A7: Công việc | B7: Người thực hiện | C7: Ưu tiên | D7: Tiến độ | E7: Deadline | F7: Giờ còn lại | G7: Cảnh báo
A8: =IFERROR(IF(LEN(TRIM(SUBSTITUTE(SUBSTITUTE(SUBSTITUTE(INDEX($V$24:$V$700,MATCH(SMALL($T$24:$T$700,ROWS($A$8:A8)),$T$24:$T$700,0)),"◆",""),"├─",""),"└─","")))=0,"⚠ Chưa nhập tên – "&INDEX($X$24:$X$700,MATCH(SMALL($T$24:$T$700,ROWS($A$8:A8)),$T$24:$T$700,0)),INDEX($V$24:$V$700,MATCH(SMALL($T$24:$T$700,ROWS($A$8:A8)),$T$24:$T$700,0))),"") | B8: =IFERROR(INDEX($Z$24:$Z$700,MATCH(SMALL($T$24:$T$700,ROWS($A$8:A8)),$T$24:$T$700,0)),"") | C8: =IFERROR(INDEX($AB$24:$AB$700,MATCH(SMALL($T$24:$T$700,ROWS($A$8:A8)),$T$24:$T$700,0)),"") | D8: =IFERROR(INDEX($AD$24:$AD$700,MATCH(SMALL($T$24:$T$700,ROWS($A$8:A8)),$T$24:$T$700,0)),"") | E8: =IFERROR(INDEX($AE$24:$AE$700,MATCH(SMALL($T$24:$T$700,ROWS($A$8:A8)),$T$24:$T$700,0)),"") | F8: =IFERROR(INDEX($AH$24:$AH$700,MATCH(SMALL($T$24:$T$700,ROWS($A$8:A8)),$T$24:$T$700,0)),"") | G8: =IFERROR(INDEX($AI$24:$AI$700,MATCH(SMALL($T$24:$T$700,ROWS($A$8:A8)),$T$24:$T$700,0)),"") | Q8: 🔴 Quá hạn
A9: =IFERROR(IF(LEN(TRIM(SUBSTITUTE(SUBSTITUTE(SUBSTITUTE(INDEX($V$24:$V$700,MATCH(SMALL($T$24:$T$700,ROWS($A$8:A9)),$T$24:$T$700,0)),"◆",""),"├─",""),"└─","")))=0,"⚠ Chưa nhập tên – "&INDEX($X$24:$X$700,MATCH(SMALL($T$24:$T$700,ROWS($A$8:A9)),$T$24:$T$700,0)),INDEX($V$24:$V$700,MATCH(SMALL($T$24:$T$700,ROWS($A$8:A9)),$T$24:$T$700,0))),"") | B9: =IFERROR(INDEX($Z$24:$Z$700,MATCH(SMALL($T$24:$T$700,ROWS($A$8:A9)),$T$24:$T$700,0)),"") | C9: =IFERROR(INDEX($AB$24:$AB$700,MATCH(SMALL($T$24:$T$700,ROWS($A$8:A9)),$T$24:$T$700,0)),"") | D9: =IFERROR(INDEX($AD$24:$AD$700,MATCH(SMALL($T$24:$T$700,ROWS($A$8:A9)),$T$24:$T$700,0)),"") | E9: =IFERROR(INDEX($AE$24:$AE$700,MATCH(SMALL($T$24:$T$700,ROWS($A$8:A9)),$T$24:$T$700,0)),"") | F9: =IFERROR(INDEX($AH$24:$AH$700,MATCH(SMALL($T$24:$T$700,ROWS($A$8:A9)),$T$24:$T$700,0)),"") | G9: =IFERROR(INDEX($AI$24:$AI$700,MATCH(SMALL($T$24:$T$700,ROWS($A$8:A9)),$T$24:$T$700,0)),"") | Q9: 🟠 Hạn trong 7 ngày
A10: =IFERROR(IF(LEN(TRIM(SUBSTITUTE(SUBSTITUTE(SUBSTITUTE(INDEX($V$24:$V$700,MATCH(SMALL($T$24:$T$700,ROWS($A$8:A10)),$T$24:$T$700,0)),"◆",""),"├─",""),"└─","")))=0,"⚠ Chưa nhập tên – "&INDEX($X$24:$X$700,MATCH(SMALL($T$24:$T$700,ROWS($A$8:A10)),$T$24:$T$700,0)),INDEX($V$24:$V$700,MATCH(SMALL($T$24:$T$700,ROWS($A$8:A10)),$T$24:$T$700,0))),"") | B10: =IFERROR(INDEX($Z$24:$Z$700,MATCH(SMALL($T$24:$T$700,ROWS($A$8:A10)),$T$24:$T$700,0)),"") | C10: =IFERROR(INDEX($AB$24:$AB$700,MATCH(SMALL($T$24:$T$700,ROWS($A$8:A10)),$T$24:$T$700,0)),"") | D10: =IFERROR(INDEX($AD$24:$AD$700,MATCH(SMALL($T$24:$T$700,ROWS($A$8:A10)),$T$24:$T$700,0)),"") | E10: =IFERROR(INDEX($AE$24:$AE$700,MATCH(SMALL($T$24:$T$700,ROWS($A$8:A10)),$T$24:$T$700,0)),"") | F10: =IFERROR(INDEX($AH$24:$AH$700,MATCH(SMALL($T$24:$T$700,ROWS($A$8:A10)),$T$24:$T$700,0)),"") | G10: =IFERROR(INDEX($AI$24:$AI$700,MATCH(SMALL($T$24:$T$700,ROWS($A$8:A10)),$T$24:$T$700,0)),"") | Q10: 🟣 P1 trọng yếu
Q11: 🟢 Theo kế hoạch / Hoàn thành
A12: ĐIỂM NHÌN QUẢN TRỊ | H12: TẢI NGUỒN LỰC | K12: NHỊP DEADLINE | O12: HÀNH ĐỘNG QUẢN TRỊ
A13: 🔴 KHẨN CẤP + P1 | D13: 🟠 KHẨN CẤP | H13: Người / Nhóm | I13: Số việc | J13: Tải phân bổ/ngày | K13: Khung thời gian | L13: Số việc | M13: Giờ còn lại | N13: Tỷ trọng | O13: Chỉ tiêu | R13: Giá trị
A14: Số công việc | C14: =COUNTIFS($AB$24:$AB$700,"P1",$AE$24:$AE$700,"<>",$AE$24:$AE$700,"<="&TODAY()+7,$AC$24:$AC$700,"<>Hoàn thành",$AC$24:$AC$700,"<>Hủy",$X$24:$X$700,"<>") -> 2 | D14: Số công việc | F14: =COUNTIFS($AB$24:$AB$700,"<>P1",$AE$24:$AE$700,"<>",$AE$24:$AE$700,"<="&TODAY()+7,$AC$24:$AC$700,"<>Hoàn thành",$AC$24:$AC$700,"<>Hủy",$X$24:$X$700,"<>") -> 6 | H14: =IFERROR(INDEX($AK$24:$AK$60,MATCH(LARGE($AN$24:$AN$60,ROWS($H$14:H14)),$AN$24:$AN$60,0)),"") -> Em Đại | I14: =IF(H14="","",INDEX($AL$24:$AL$60,MATCH(H14,$AK$24:$AK$60,0))) -> 61 | J14: =IF(H14="","",INDEX($AM$24:$AM$60,MATCH(H14,$AK$24:$AK$60,0))) -> 35.2 | K14: 🔴 Quá hạn | L14: =COUNTIFS($X$24:$X$700,"<>",$AI$24:$AI$700,"🔴*") -> 5 | M14: =SUMIFS($AH$24:$AH$700,$X$24:$X$700,"<>",$AI$24:$AI$700,"🔴*") -> 424 | N14: =IFERROR(L14/$B$4,0) -> 0.044247788 | O14: Thiếu người thực hiện | R14: =COUNTIFS($X$24:$X$700,"<>",$AJ$24:$AJ$700,"Thiếu người*") -> 0
A15: Giờ còn lại | C15: =SUMIFS($AH$24:$AH$700,$AB$24:$AB$700,"P1",$AE$24:$AE$700,"<>",$AE$24:$AE$700,"<="&TODAY()+7,$AC$24:$AC$700,"<>Hoàn thành",$AC$24:$AC$700,"<>Hủy",$X$24:$X$700,"<>") -> 16 | D15: Giờ còn lại | F15: =SUMIFS($AH$24:$AH$700,$AB$24:$AB$700,"<>P1",$AE$24:$AE$700,"<>",$AE$24:$AE$700,"<="&TODAY()+7,$AC$24:$AC$700,"<>Hoàn thành",$AC$24:$AC$700,"<>Hủy",$X$24:$X$700,"<>") -> 544 | H15: =IFERROR(INDEX($AK$24:$AK$60,MATCH(LARGE($AN$24:$AN$60,ROWS($H$14:H15)),$AN$24:$AN$60,0)),"") -> GĐ BOC | I15: =IF(H15="","",INDEX($AL$24:$AL$60,MATCH(H15,$AK$24:$AK$60,0))) -> 4 | J15: =IF(H15="","",INDEX($AM$24:$AM$60,MATCH(H15,$AK$24:$AK$60,0))) -> 5 | K15: 🟠 0–7 ngày | L15: =COUNTIFS($X$24:$X$700,"<>",$AI$24:$AI$700,"🟠*") -> 3 | M15: =SUMIFS($AH$24:$AH$700,$X$24:$X$700,"<>",$AI$24:$AI$700,"🟠*") -> 136 | N15: =IFERROR(L15/$B$4,0) -> 0.026548673 | O15: Thiếu tên công việc | R15: =SUMPRODUCT(--($X$24:$X$700<>""),--(LEN(TRIM(SUBSTITUTE(SUBSTITUTE(SUBSTITUTE($V$24:$V$700,"◆",""),"├─",""),"└─","")))=0)) -> #REF!
H16: =IFERROR(INDEX($AK$24:$AK$60,MATCH(LARGE($AN$24:$AN$60,ROWS($H$14:H16)),$AN$24:$AN$60,0)),"") -> Thu Trang | I16: =IF(H16="","",INDEX($AL$24:$AL$60,MATCH(H16,$AK$24:$AK$60,0))) -> 1 | J16: =IF(H16="","",INDEX($AM$24:$AM$60,MATCH(H16,$AK$24:$AK$60,0))) -> 0 | K16: 🟡 8–30 ngày | L16: =COUNTIFS($AE$24:$AE$700,">"&TODAY()+7,$AE$24:$AE$700,"<="&TODAY()+30,$AC$24:$AC$700,"<>Hoàn thành",$AC$24:$AC$700,"<>Hủy",$X$24:$X$700,"<>") -> 15 | M16: =SUMIFS($AH$24:$AH$700,$AE$24:$AE$700,">"&TODAY()+7,$AE$24:$AE$700,"<="&TODAY()+30,$AC$24:$AC$700,"<>Hoàn thành",$AC$24:$AC$700,"<>Hủy",$X$24:$X$700,"<>") -> 1076 | N16: =IFERROR(L16/$B$4,0) -> 0.13274336 | O16: Cảnh báo quá tải | R16: =COUNTIFS($X$24:$X$700,"<>",$AJ$24:$AJ$700,"Quá tải*") -> 22
A17: 🟣 TRỌNG YẾU CHƯA GẤP | D17: 🟢 THEO KẾ HOẠCH / HOÀN THÀNH | H17: =IFERROR(INDEX($AK$24:$AK$60,MATCH(LARGE($AN$24:$AN$60,ROWS($H$14:H17)),$AN$24:$AN$60,0)),"") -> Team PTSP | I17: =IF(H17="","",INDEX($AL$24:$AL$60,MATCH(H17,$AK$24:$AK$60,0))) -> 2 | J17: =IF(H17="","",INDEX($AM$24:$AM$60,MATCH(H17,$AK$24:$AK$60,0))) -> 0 | K17: 🔵 Trên 30 ngày | L17: =COUNTIFS($AE$24:$AE$700,">"&TODAY()+30,$AC$24:$AC$700,"<>Hoàn thành",$AC$24:$AC$700,"<>Hủy",$X$24:$X$700,"<>") -> 73 | M17: =SUMIFS($AH$24:$AH$700,$AE$24:$AE$700,">"&TODAY()+30,$AC$24:$AC$700,"<>Hoàn thành",$AC$24:$AC$700,"<>Hủy",$X$24:$X$700,"<>") -> 5404 | N17: =IFERROR(L17/$B$4,0) -> 0.6460177 | O17: Tiến độ đang ở 0% | R17: =COUNTIFS($AD$24:$AD$700,0,$AD$24:$AD$700,"<>",$AC$24:$AC$700,"<>Hoàn thành",$AC$24:$AC$700,"<>Hủy",$AC$24:$AC$700,"<>Chưa lên lịch",$AC$24:$AC$700,"<>Đã lên lịch",$X$24:$X$700,"<>") -> 82
A18: Số công việc | C18: =COUNTIFS($AB$24:$AB$700,"P1",$AE$24:$AE$700,">"&TODAY()+7,$AC$24:$AC$700,"<>Hoàn thành",$AC$24:$AC$700,"<>Hủy",$X$24:$X$700,"<>") -> 32 | D18: Số công việc | F18: =COUNTIFS($X$24:$X$700,"<>",$AI$24:$AI$700,"🟢*") -> 57 | H18: =IFERROR(INDEX($AK$24:$AK$60,MATCH(LARGE($AN$24:$AN$60,ROWS($H$14:H18)),$AN$24:$AN$60,0)),"") -> Ms Trang | I18: =IF(H18="","",INDEX($AL$24:$AL$60,MATCH(H18,$AK$24:$AK$60,0))) -> 32 | J18: =IF(H18="","",INDEX($AM$24:$AM$60,MATCH(H18,$AK$24:$AK$60,0))) -> 0 | K18: ⚪ Chưa có hạn | L18: =COUNTIFS($X$24:$X$700,"<>",$AE$24:$AE$700,"",$AC$24:$AC$700,"<>Hoàn thành",$AC$24:$AC$700,"<>Hủy") -> 9 | M18: =SUMIFS($AH$24:$AH$700,$X$24:$X$700,"<>",$AE$24:$AE$700,"",$AC$24:$AC$700,"<>Hoàn thành",$AC$24:$AC$700,"<>Hủy") -> 420 | N18: =IFERROR(L18/$B$4,0) -> 0.079646018 | O18: L6 thiếu mã / liên kết | R18: =COUNTIFS('Lớp 6 - Chi tiết'!$S$14:$S$267,"<>",'Lớp 6 - Chi tiết'!$I$14:$I$267,"") -> 0
A19: Giờ còn lại | C19: =SUMIFS($AH$24:$AH$700,$AB$24:$AB$700,"P1",$AE$24:$AE$700,">"&TODAY()+7,$AC$24:$AC$700,"<>Hoàn thành",$AC$24:$AC$700,"<>Hủy",$X$24:$X$700,"<>") -> 2984 | D19: Giờ còn lại | F19: =SUMIFS($AH$24:$AH$700,$X$24:$X$700,"<>",$AI$24:$AI$700,"🟢*") -> 3496 | K19: ✅ Hoàn thành | L19: =COUNTIFS($X$24:$X$700,"<>",$AC$24:$AC$700,"Hoàn thành") -> 1 | M19: =SUMIFS($AH$24:$AH$700,$X$24:$X$700,"<>",$AC$24:$AC$700,"Hoàn thành") -> 0 | N19: =IFERROR(L19/$B$4,0) -> 0.0088495575 | O19: Tỷ lệ công việc hoàn thành | R19: =IFERROR(COUNTIFS($X$24:$X$700,"<>",$AC$24:$AC$700,"Hoàn thành")/$B$4,0) -> 0.0088495575
A20: * Công việc chưa có deadline được tách riêng trong khối Sức khỏe dữ liệu để tránh hiểu sai mức độ cấp bách. | H20: Xếp hạng theo tổng tải phân bổ giờ/ngày; dùng để cân bằng nguồn lực. | O20: Mức cảnh báo chung | R20: =IF(OR($H$4/$B$4>=15%,$R$21/$B$4>=15%),"🔴 Căng thẳng",IF(OR(($H$4+$K$4)/$B$4>=15%,$R$21/$B$4>=5%),"🟠 Cần chú ý","🟢 Ổn định")) -> #REF!
A21: CÂY PHÂN RÃ CÔNG VIỆC L3–L6 • Mã phân cấp nằm trong tên để nhận biết quan hệ cha–con | O21: Lệch trạng thái / thời gian | R21: =SUMPRODUCT(--(LEN('Lớp 3 - Công việc chính'!$AS$14:$AS$73)>0),--('Lớp 3 - Công việc chính'!$AS$14:$AS$73<>"OK"))+SUMPRODUCT(--(LEN('Lớp 4 - Danh mục'!$AV$14:$AV$132)>0),--('Lớp 4 - Danh mục'!$AV$14:$AV$132<>"OK"))+SUMPRODUCT(--(LEN('Lớp 5 - Phân công'!$AW$14:$AW$262)>0),--('Lớp 5 - Phân công'!$AW$14:$AW$262<>"OK"))+SUMPRODUCT(--(LEN('Lớp 6 - Chi tiết'!$AZ$14:$AZ$267)>0),--('Lớp 6 - Chi tiết'!$AZ$14:$AZ$267<>"OK")) -> #REF!
A22: CÂY PHÂN RÃ CÔNG VIỆC | B22: CHỦ TRÌ | C22: ĐƠN VỊ | D22: ƯU TIÊN | E22: TRẠNG THÁI | F22: TIẾN ĐỘ | G22: DEADLINE | H22: CÒN NGÀY | I22: GIỜ CÒN | J22: CẢNH BÁO | K22: HÀNH ĐỘNG / KIỂM SOÁT | L22: VỊ TRÍ DỮ LIỆU GỐC | M22: TẢI QUY ĐỔI/NGÀY | N22: ĐÁNH GIÁ PHÂN BỔ
A23: =IF($T23="","",LET(p,$T23,m,MATCH(p,$AS$24:$AS$700,0),lvl,INDEX($W$24:$W$700,m),SWITCH(lvl,3,"▓▓ L3 "&p&" "&UPPER(IF(INDEX($AT$24:$AT$700,m)="","⚠ CHƯA NHẬP TÊN",INDEX($AT$24:$AT$700,m))),4," ├─ ▓ L4 "&p&" "&IF(INDEX($AU$24:$AU$700,m)="","⚠ Chưa nhập tên",INDEX($AU$24:$AU$700,m)),5," ├── ▒ L5 "&p&" "&IF(INDEX($AV$24:$AV$700,m)="","⚠ Chưa nhập tên công việc",INDEX($AV$24:$AV$700,m)),6," └─── ░ L6 "&p&" "&IF(INDEX($AW$24:$AW$700,m)="","⚠ Chưa nhập tên chi tiết",INDEX($AW$24:$AW$700,m)),""))) -> ▓▓ L3 01 XÂY DỰNG BỘ CHIẾN LƯỢC CÔNG TY TẦM NHÌN 2030 | B23: =IF($T23="","",INDEX($AX$24:$AX$700,MATCH($T23,$AS$24:$AS$700,0))) -> GĐ BOC | C23: =IF($T23="","",INDEX($AY$24:$AY$700,MATCH($T23,$AS$24:$AS$700,0))) -> Công ty | D23: =IF($T23="","",INDEX($AZ$24:$AZ$700,MATCH($T23,$AS$24:$AS$700,0))) -> P1 | E23: =IF($T23="","",INDEX($BA$24:$BA$700,MATCH($T23,$AS$24:$AS$700,0))) -> Đã lên lịch | F23: =IF($T23="","",INDEX($BB$24:$BB$700,MATCH($T23,$AS$24:$AS$700,0))) | G23: =IF($T23="","",INDEX($BC$24:$BC$700,MATCH($T23,$AS$24:$AS$700,0))) -> 46420 | H23: =IF($T23="","",INDEX($BD$24:$BD$700,MATCH($T23,$AS$24:$AS$700,0))) -> 68 | I23: =IF($T23="","",INDEX($BF$24:$BF$700,MATCH($T23,$AS$24:$AS$700,0))) -> 200 | J23: =IF($T23="","",INDEX($BG$24:$BG$700,MATCH($T23,$AS$24:$AS$700,0))) -> 🟣 P1 trọng yếu | K23: =IF($T23="","",INDEX($BH$24:$BH$700,MATCH($T23,$AS$24:$AS$700,0))) -> Bình thường – tổng 2.6/8.0 giờ/ngày | L23: {=IF($T23="","",LET(m,MATCH($T23,$AS$24:$AS$700,0),lvl,INDEX($W$24:$W$700,m),id,INDEX($X$24:$X$700,m),SWITCH(lvl,3,"Lớp 3 - Công việc chính!A"&MATCH(id,'Lớp 3 - Công việc chính'!$I$1:$I$73,0),4,"Lớp 4 - Danh mục!A"&MATCH(id,'Lớp 4 - Danh mục'!$I$1:$I$132,0),5,"Lớp 5 - Phân công!A"&MATCH(id,'Lớp 5 - Phân công'!$I$1:$I$262,0),6,"Lớp 6 - Chi tiết!A"&MATCH(id,'Lớp 6 - Chi tiết'!$I$1:$I$267,0))))} -> Lớp 3 - Công việc chính!A14 | M23: =IF($T23="","",INDEX($BI$24:$BI$700,MATCH($T23,$AS$24:$AS$700,0))) -> 0.6 | N23: =IF($T23="","",INDEX($BJ$24:$BJ$700,MATCH($T23,$AS$24:$AS$700,0))) -> Thiếu 11.7 giờ/tuần | T23: =IFERROR(__xludf.DUMMYFUNCTION("SORT(FILTER($AS$24:$AS$700,$X$24:$X$700<>""""),1,1)"),"01") -> 01 | U23: SortKey | V23: TreeNode | W23: Level | X23: ID | Y23: ParentID | Z23: Owner | AA23: Unit | AB23: Priority | AC23: Status | AD23: Progress | AE23: Deadline | AF23: DaysLeft | AG23: Hours | AH23: HoursRemain | AI23: Warning | AJ23: Control | AK23: OwnerList | AL23: TaskCount | AM23: HoursRemain | AS23: STT phân cấp | AT23: L3 | AU23: L4 | AV23: L5 | AW23: L6 | AX23: Owner | AY23: Unit | AZ23: Priority | BA23: Status | BB23: Progress | BC23: Deadline | BD23: DaysLeft | BE23: Hours | BF23: HoursRemain | BG23: Warning | BH23: Control | BI23: DailyLoadEquivalent | BJ23: AllocationCheck
A24: =IF($T24="","",LET(p,$T24,m,MATCH(p,$AS$24:$AS$700,0),lvl,INDEX($W$24:$W$700,m),SWITCH(lvl,3,"▓▓ L3 "&p&" "&UPPER(IF(INDEX($AT$24:$AT$700,m)="","⚠ CHƯA NHẬP TÊN",INDEX($AT$24:$AT$700,m))),4," ├─ ▓ L4 "&p&" "&IF(INDEX($AU$24:$AU$700,m)="","⚠ Chưa nhập tên",INDEX($AU$24:$AU$700,m)),5," ├── ▒ L5 "&p&" "&IF(INDEX($AV$24:$AV$700,m)="","⚠ Chưa nhập tên công việc",INDEX($AV$24:$AV$700,m)),6," └─── ░ L6 "&p&" "&IF(INDEX($AW$24:$AW$700,m)="","⚠ Chưa nhập tên chi tiết",INDEX($AW$24:$AW$700,m)),""))) -> ▓▓ L3 02 XÂY DỰNG BỘ VHDN | B24: =IF($T24="","",INDEX($AX$24:$AX$700,MATCH($T24,$AS$24:$AS$700,0))) -> GĐ BOC | C24: =IF($T24="","",INDEX($AY$24:$AY$700,MATCH($T24,$AS$24:$AS$700,0))) -> Công ty | D24: =IF($T24="","",INDEX($AZ$24:$AZ$700,MATCH($T24,$AS$24:$AS$700,0))) -> P2 | E24: =IF($T24="","",INDEX($BA$24:$BA$700,MATCH($T24,$AS$24:$AS$700,0))) -> Đã lên lịch | F24: =IF($T24="","",INDEX($BB$24:$BB$700,MATCH($T24,$AS$24:$AS$700,0))) | G24: =IF($T24="","",INDEX($BC$24:$BC$700,MATCH($T24,$AS$24:$AS$700,0))) -> 46420 | H24: =IF($T24="","",INDEX($BD$24:$BD$700,MATCH($T24,$AS$24:$AS$700,0))) -> 68 | I24: =IF($T24="","",INDEX($BF$24:$BF$700,MATCH($T24,$AS$24:$AS$700,0))) -> 100 | J24: =IF($T24="","",INDEX($BG$24:$BG$700,MATCH($T24,$AS$24:$AS$700,0))) -> 🟢 Theo kế hoạch | K24: =IF($T24="","",INDEX($BH$24:$BH$700,MATCH($T24,$AS$24:$AS$700,0))) -> Bình thường – tổng 2.6/8.0 giờ/ngày | L24: {=IF($T24="","",LET(m,MATCH($T24,$AS$24:$AS$700,0),lvl,INDEX($W$24:$W$700,m),id,INDEX($X$24:$X$700,m),SWITCH(lvl,3,"Lớp 3 - Công việc chính!A"&MATCH(id,'Lớp 3 - Công việc chính'!$I$1:$I$73,0),4,"Lớp 4 - Danh mục!A"&MATCH(id,'Lớp 4 - Danh mục'!$I$1:$I$132,0),5,"Lớp 5 - Phân công!A"&MATCH(id,'Lớp 5 - Phân công'!$I$1:$I$262,0),6,"Lớp 6 - Chi tiết!A"&MATCH(id,'Lớp 6 - Chi tiết'!$I$1:$I$267,0))))} -> Lớp 3 - Công việc chính!A15 | M24: =IF($T24="","",INDEX($BI$24:$BI$700,MATCH($T24,$AS$24:$AS$700,0))) -> 2 | N24: =IF($T24="","",INDEX($BJ$24:$BJ$700,MATCH($T24,$AS$24:$AS$700,0))) -> Thiếu 4.4 giờ/tuần | T24: =IFERROR(__xludf.DUMMYFUNCTION("""COMPUTED_VALUE"""),"02") -> 02 | U24: =IF('Lớp 3 - Công việc chính'!I14="","",'Lớp 3 - Công việc chính'!I14) -> HHL3CT01 | V24: =IF('Lớp 3 - Công việc chính'!I14="","","◆ "&'Lớp 3 - Công việc chính'!M14) -> ◆ Xây dựng bộ chiến lược công ty tầm nhìn 2030 | W24: =IF('Lớp 3 - Công việc chính'!I14="","",3) -> 3 | X24: ='Lớp 3 - Công việc chính'!I14 -> HHL3CT01 | Y24: =IF(X24="","","") | Z24: ='Lớp 3 - Công việc chính'!V14 -> GĐ BOC | AA24: ='Lớp 3 - Công việc chính'!W14 -> Công ty | AB24: ='Lớp 3 - Công việc chính'!Y14 -> P1 | AC24: ='Lớp 3 - Công việc chính'!X14 -> Đã lên lịch | AD24: ='Lớp 3 - Công việc chính'!AC14 | AE24: ='Lớp 3 - Công việc chính'!AA14 -> 46420 | AF24: ='Lớp 3 - Công việc chính'!AD14 -> 68 | AG24: ='Lớp 3 - Công việc chính'!AE14 -> 200 | AH24: =IF(AG24="","",AG24*(1-AD24)) -> 200 | AI24: {=IF($X24="","",LET(tw,SWITCH($W24,3,IFERROR(INDEX('Lớp 3 - Công việc chính'!$AG$14:$AG$73,MATCH($X24,'Lớp 3 - Công việc chính'!$I$14:$I$73,0)),""),4,IFERROR(INDEX('Lớp 4 - Danh mục'!$AJ$14:$AJ$132,MATCH($X24,'Lớp 4 - Danh mục'!$I$14:$I$132,0)),""),5,IFERROR(INDEX('Lớp 5 - Phân công'!$AK$14:$AK$262,MATCH($X24,'Lớp 5 - Phân công'!$I$14:$I$262,0)),""),6,IFERROR(INDEX('Lớp 6 - Chi tiết'!$AN$14:$AN$267,MATCH($X24,'Lớp 6 - Chi tiết'!$I$14:$I$267,0)),""),""),std,IF(AC24="Hoàn thành","🟢 Hoàn thành",IF(AC24="Hủy","⚪ Hủy",IF(AE24="","🔵 Chưa có hạn",IF(AE24<TODAY(),"🔴 Quá hạn",IF(AE24<=TODAY()+7,"🟠 Hạn ≤7 ngày",IF(AB24="P1","🟣 P1 trọng yếu","🟢 Theo kế hoạch")))))),IF(ISNUMBER(SEARCH("Cảnh báo",tw)),"🟡 Con vượt khung gốc",std)))} -> 🟣 P1 trọng yếu | AJ24: ='Lớp 3 - Công việc chính'!AH14 -> Bình thường – tổng 2.6/8.0 giờ/ngày | AK24: =IFERROR(__xludf.DUMMYFUNCTION("SORT(UNIQUE(FILTER($Z$24:$Z$700,($Z$24:$Z$700<>"""")*($X$24:$X$700<>""""))))"),"Em Đại") -> Em Đại | AL24: =IF(AK24="","",COUNTIF($Z$24:$Z$700,AK24)) -> 61 | AM24: =IF(AK24="","",SUMIF($Z$24:$Z$700,AK24,$BI$24:$BI$700)) -> 35.2 | AN24: =IF(AK24="","",AM24+ROW()/1000000) -> 35.200024 | AS24: =IF(X24="","",TEXT(COUNTIF($X$24:X24,"<>"),"00")) -> 01 | AT24: =IF(W24=3,TRIM(SUBSTITUTE(V24,"◆","")),"") -> Xây dựng bộ chiến lược công ty tầm nhìn 2030 | AU24: =IF(W24=4,TRIM(SUBSTITUTE(V24,"├─","")),"") | AV24: =IF(W24=5,TRIM(SUBSTITUTE(V24,"├─","")),"") | AW24: =IF(W24=6,TRIM(SUBSTITUTE(SUBSTITUTE(V24,"└─",""),"├─","")),"") | AX24: =Z24 -> GĐ BOC | AY24: =AA24 -> Công ty | AZ24: =AB24 -> P1 | BA24: =AC24 -> Đã lên lịch | BB24: =AD24 | BC24: =AE24 -> 46420 | BD24: =AF24 -> 68 | BE24: =AG24 -> 200 | ... BH24: =AJ24 -> Bình thường – tổng 2.6/8.0 giờ/ngày | BI24: {=IF($X24="","",SWITCH($W24,3,IFERROR(INDEX('Lớp 3 - Công việc chính'!$AF$14:$AF$73,MATCH($X24,'Lớp 3 - Công việc chính'!$I$14:$I$73,0)),""),4,IFERROR(INDEX('Lớp 4 - Danh mục'!$AI$14:$AI$132,MATCH($X24,'Lớp 4 - Danh mục'!$I$14:$I$132,0)),""),5,IFERROR(INDEX('Lớp 5 - Phân công'!$AJ$14:$AJ$262,MATCH($X24,'Lớp 5 - Phân công'!$I$14:$I$262,0)),""),6,IFERROR(INDEX('Lớp 6 - Chi tiết'!$AM$14:$AM$267,MATCH($X24,'Lớp 6 - Chi tiết'!$I$14:$I$267,0)),""),""))} -> 0.6 | BJ24: {=IF($X24="","",SWITCH($W24,3,IFERROR(INDEX('Lớp 3 - Công việc chính'!$AR$14:$AR$73,MATCH($X24,'Lớp 3 - Công việc chính'!$I$14:$I$73,0)),""),4,IFERROR(INDEX('Lớp 4 - Danh mục'!$AU$14:$AU$132,MATCH($X24,'Lớp 4 - Danh mục'!$I$14:$I$132,0)),""),5,IFERROR(INDEX('Lớp 5 - Phân công'!$AV$14:$AV$262,MATCH($X24,'Lớp 5 - Phân công'!$I$14:$I$262,0)),""),6,IFERROR(INDEX('Lớp 6 - Chi tiết'!$AY$14:$AY$267,MATCH($X24,'Lớp 6 - Chi tiết'!$I$14:$I$267,0)),""),""))} -> Thiếu 11.7 giờ/tuần
A25: =IF($T25="","",LET(p,$T25,m,MATCH(p,$AS$24:$AS$700,0),lvl,INDEX($W$24:$W$700,m),SWITCH(lvl,3,"▓▓ L3 "&p&" "&UPPER(IF(INDEX($AT$24:$AT$700,m)="","⚠ CHƯA NHẬP TÊN",INDEX($AT$24:$AT$700,m))),4," ├─ ▓ L4 "&p&" "&IF(INDEX($AU$24:$AU$700,m)="","⚠ Chưa nhập tên",INDEX($AU$24:$AU$700,m)),5," ├── ▒ L5 "&p&" "&IF(INDEX($AV$24:$AV$700,m)="","⚠ Chưa nhập tên công việc",INDEX($AV$24:$AV$700,m)),6," └─── ░ L6 "&p&" "&IF(INDEX($AW$24:$AW$700,m)="","⚠ Chưa nhập tên chi tiết",INDEX($AW$24:$AW$700,m)),""))) -> ▓▓ L3 03 KHKD 2027& HT LẬP KH THEO THAM SỐ KD (BÁN TỰ ĐỘNG) | B25: =IF($T25="","",INDEX($AX$24:$AX$700,MATCH($T25,$AS$24:$AS$700,0))) -> Em Đại | C25: =IF($T25="","",INDEX($AY$24:$AY$700,MATCH($T25,$AS$24:$AS$700,0))) -> Dữ liệu điều hành | D25: =IF($T25="","",INDEX($AZ$24:$AZ$700,MATCH($T25,$AS$24:$AS$700,0))) -> P1 | E25: =IF($T25="","",INDEX($BA$24:$BA$700,MATCH($T25,$AS$24:$AS$700,0))) -> Đang thực hiện | F25: =IF($T25="","",INDEX($BB$24:$BB$700,MATCH($T25,$AS$24:$AS$700,0))) -> 0 | G25: =IF($T25="","",INDEX($BC$24:$BC$700,MATCH($T25,$AS$24:$AS$700,0))) -> 46337 | H25: =IF($T25="","",INDEX($BD$24:$BD$700,MATCH($T25,$AS$24:$AS$700,0))) -> 77 | I25: =IF($T25="","",INDEX($BF$24:$BF$700,MATCH($T25,$AS$24:$AS$700,0))) -> 620 | J25: =IF($T25="","",INDEX($BG$24:$BG$700,MATCH($T25,$AS$24:$AS$700,0))) -> 🟣 P1 trọng yếu | K25: =IF($T25="","",INDEX($BH$24:$BH$700,MATCH($T25,$AS$24:$AS$700,0))) -> Theo dõi tải tại Lớp 4 | L25: {=IF($T25="","",LET(m,MATCH($T25,$AS$24:$AS$700,0),lvl,INDEX($W$24:$W$700,m),id,INDEX($X$24:$X$700,m),SWITCH(lvl,3,"Lớp 3 - Công việc chính!A"&MATCH(id,'Lớp 3 - Công việc chính'!$I$1:$I$73,0),4,"Lớp 4 - Danh mục!A"&MATCH(id,'Lớp 4 - Danh mục'!$I$1:$I$132,0),5,"Lớp 5 - Phân công!A"&MATCH(id,'Lớp 5 - Phân công'!$I$1:$I$262,0),6,"Lớp 6 - Chi tiết!A"&MATCH(id,'Lớp 6 - Chi tiết'!$I$1:$I$267,0))))} -> Lớp 3 - Công việc chính!A16 | M25: =IF($T25="","",INDEX($BI$24:$BI$700,MATCH($T25,$AS$24:$AS$700,0))) | N25: =IF($T25="","",INDEX($BJ$24:$BJ$700,MATCH($T25,$AS$24:$AS$700,0))) -> Theo dõi phân bổ tại Lớp 4 | T25: =IFERROR(__xludf.DUMMYFUNCTION("""COMPUTED_VALUE"""),"03") -> 03 | U25: =IF('Lớp 3 - Công việc chính'!I15="","",'Lớp 3 - Công việc chính'!I15) -> HHL3CT02 | V25: =IF('Lớp 3 - Công việc chính'!I15="","","◆ "&'Lớp 3 - Công việc chính'!M15) -> ◆ Xây dựng bộ VHDN | W25: =IF('Lớp 3 - Công việc chính'!I15="","",3) -> 3 | X25: ='Lớp 3 - Công việc chính'!I15 -> HHL3CT02 | Y25: =IF(X25="","","") | Z25: ='Lớp 3 - Công việc chính'!V15 -> GĐ BOC | AA25: ='Lớp 3 - Công việc chính'!W15 -> Công ty | AB25: ='Lớp 3 - Công việc chính'!Y15 -> P2 | AC25: ='Lớp 3 - Công việc chính'!X15 -> Đã lên lịch | AD25: ='Lớp 3 - Công việc chính'!AC15 | AE25: ='Lớp 3 - Công việc chính'!AA15 -> 46420 | AF25: ='Lớp 3 - Công việc chính'!AD15 -> 68 | AG25: ='Lớp 3 - Công việc chính'!AE15 -> 100 | AH25: =IF(AG25="","",AG25*(1-AD25)) -> 100 | AI25: =IF(AC25="Hoàn thành","🟢 Hoàn thành",IF(AC25="Hủy","⚪ Hủy",IF(AE25="","🔵 Chưa có hạn",IF(AE25<TODAY(),"🔴 Quá hạn",IF(AE25<=TODAY()+7,"🟠 Hạn ≤7 ngày",IF(AB25="P1","🟣 P1 trọng yếu","🟢 Theo kế hoạch")))))) -> 🟢 Theo kế hoạch | AJ25: ='Lớp 3 - Công việc chính'!AH15 -> Bình thường – tổng 2.6/8.0 giờ/ngày | AK25: =IFERROR(__xludf.DUMMYFUNCTION("""COMPUTED_VALUE"""),"GĐ BOC") -> GĐ BOC | AL25: =IF(AK25="","",COUNTIF($Z$24:$Z$700,AK25)) -> 4 | AM25: =IF(AK25="","",SUMIF($Z$24:$Z$700,AK25,$BI$24:$BI$700)) -> 5 | AN25: =IF(AK25="","",AM25+ROW()/1000000) -> 5.000025 | AS25: =IF(X25="","",TEXT(COUNTIF($X$24:X25,"<>"),"00")) -> 02 | AT25: =IF(W25=3,TRIM(SUBSTITUTE(V25,"◆","")),"") -> Xây dựng bộ VHDN | AU25: =IF(W25=4,TRIM(SUBSTITUTE(V25,"├─","")),"") | AV25: =IF(W25=5,TRIM(SUBSTITUTE(V25,"├─","")),"") | AW25: =IF(W25=6,TRIM(SUBSTITUTE(SUBSTITUTE(V25,"└─",""),"├─","")),"") | AX25: =Z25 -> GĐ BOC | AY25: =AA25 -> Công ty | AZ25: =AB25 -> P2 | BA25: =AC25 -> Đã lên lịch | BB25: =AD25 | BC25: =AE25 -> 46420 | BD25: =AF25 -> 68 | BE25: =AG25 -> 100 | ... BH25: =AJ25 -> Bình thường – tổng 2.6/8.0 giờ/ngày | BI25: {=IF($X25="","",SWITCH($W25,3,IFERROR(INDEX('Lớp 3 - Công việc chính'!$AF$14:$AF$73,MATCH($X25,'Lớp 3 - Công việc chính'!$I$14:$I$73,0)),""),4,IFERROR(INDEX('Lớp 4 - Danh mục'!$AI$14:$AI$132,MATCH($X25,'Lớp 4 - Danh mục'!$I$14:$I$132,0)),""),5,IFERROR(INDEX('Lớp 5 - Phân công'!$AJ$14:$AJ$262,MATCH($X25,'Lớp 5 - Phân công'!$I$14:$I$262,0)),""),6,IFERROR(INDEX('Lớp 6 - Chi tiết'!$AM$14:$AM$267,MATCH($X25,'Lớp 6 - Chi tiết'!$I$14:$I$267,0)),""),""))} -> 2 | BJ25: {=IF($X25="","",SWITCH($W25,3,IFERROR(INDEX('Lớp 3 - Công việc chính'!$AR$14:$AR$73,MATCH($X25,'Lớp 3 - Công việc chính'!$I$14:$I$73,0)),""),4,IFERROR(INDEX('Lớp 4 - Danh mục'!$AU$14:$AU$132,MATCH($X25,'Lớp 4 - Danh mục'!$I$14:$I$132,0)),""),5,IFERROR(INDEX('Lớp 5 - Phân công'!$AV$14:$AV$262,MATCH($X25,'Lớp 5 - Phân công'!$I$14:$I$262,0)),""),6,IFERROR(INDEX('Lớp 6 - Chi tiết'!$AY$14:$AY$267,MATCH($X25,'Lớp 6 - Chi tiết'!$I$14:$I$267,0)),""),""))} -> Thiếu 4.4 giờ/tuần
A26: =IF($T26="","",LET(p,$T26,m,MATCH(p,$AS$24:$AS$700,0),lvl,INDEX($W$24:$W$700,m),SWITCH(lvl,3,"▓▓ L3 "&p&" "&UPPER(IF(INDEX($AT$24:$AT$700,m)="","⚠ CHƯA NHẬP TÊN",INDEX($AT$24:$AT$700,m))),4," ├─ ▓ L4 "&p&" "&IF(INDEX($AU$24:$AU$700,m)="","⚠ Chưa nhập tên",INDEX($AU$24:$AU$700,m)),5," ├── ▒ L5 "&p&" "&IF(INDEX($AV$24:$AV$700,m)="","⚠ Chưa nhập tên công việc",INDEX($AV$24:$AV$700,m)),6," └─── ░ L6 "&p&" "&IF(INDEX($AW$24:$AW$700,m)="","⚠ Chưa nhập tên chi tiết",INDEX($AW$24:$AW$700,m)),""))) -> ├─ ▓ L4 03.01 Xác nhận công thức & tạo HT tham số cho KH GT | B26: =IF($T26="","",INDEX($AX$24:$AX$700,MATCH($T26,$AS$24:$AS$700,0))) -> Em Đại | C26: =IF($T26="","",INDEX($AY$24:$AY$700,MATCH($T26,$AS$24:$AS$700,0))) -> Dữ liệu điều hành | D26: =IF($T26="","",INDEX($AZ$24:$AZ$700,MATCH($T26,$AS$24:$AS$700,0))) -> P1 | E26: =IF($T26="","",INDEX($BA$24:$BA$700,MATCH($T26,$AS$24:$AS$700,0))) -> Chưa bắt đầu | F26: =IF($T26="","",INDEX($BB$24:$BB$700,MATCH($T26,$AS$24:$AS$700,0))) -> 0 | G26: =IF($T26="","",INDEX($BC$24:$BC$700,MATCH($T26,$AS$24:$AS$700,0))) -> 46305 | H26: =IF($T26="","",INDEX($BD$24:$BD$700,MATCH($T26,$AS$24:$AS$700,0))) -> 50 | I26: =IF($T26="","",INDEX($BF$24:$BF$700,MATCH($T26,$AS$24:$AS$700,0))) -> 140 | J26: =IF($T26="","",INDEX($BG$24:$BG$700,MATCH($T26,$AS$24:$AS$700,0))) -> 🟣 P1 trọng yếu | K26: =IF($T26="","",INDEX($BH$24:$BH$700,MATCH($T26,$AS$24:$AS$700,0))) -> Theo dõi tải tại Lớp 5 | L26: {=IF($T26="","",LET(m,MATCH($T26,$AS$24:$AS$700,0),lvl,INDEX($W$24:$W$700,m),id,INDEX($X$24:$X$700,m),SWITCH(lvl,3,"Lớp 3 - Công việc chính!A"&MATCH(id,'Lớp 3 - Công việc chính'!$I$1:$I$73,0),4,"Lớp 4 - Danh mục!A"&MATCH(id,'Lớp 4 - Danh mục'!$I$1:$I$132,0),5,"Lớp 5 - Phân công!A"&MATCH(id,'Lớp 5 - Phân công'!$I$1:$I$262,0),6,"Lớp 6 - Chi tiết!A"&MATCH(id,'Lớp 6 - Chi tiết'!$I$1:$I$267,0))))} -> Lớp 4 - Danh mục!A14 | M26: =IF($T26="","",INDEX($BI$24:$BI$700,MATCH($T26,$AS$24:$AS$700,0))) | N26: =IF($T26="","",INDEX($BJ$24:$BJ$700,MATCH($T26,$AS$24:$AS$700,0))) -> Theo dõi phân bổ tại Lớp 5 | T26: =IFERROR(__xludf.DUMMYFUNCTION("""COMPUTED_VALUE"""),"03.01") -> 03.01 | U26: =IF('Lớp 3 - Công việc chính'!I16="","",'Lớp 3 - Công việc chính'!I16) -> HHL3CT03 | V26: =IF('Lớp 3 - Công việc chính'!I16="","","◆ "&'Lớp 3 - Công việc chính'!M16) -> ◆ KHKD 2027& HT lập KH theo tham số KD (bán tự động) | W26: =IF('Lớp 3 - Công việc chính'!I16="","",3) -> 3 | X26: ='Lớp 3 - Công việc chính'!I16 -> HHL3CT03 | Y26: =IF(X26="","","") | Z26: ='Lớp 3 - Công việc chính'!V16 -> Em Đại | AA26: ='Lớp 3 - Công việc chính'!W16 -> Dữ liệu điều hành | AB26: ='Lớp 3 - Công việc chính'!Y16 -> P1 | AC26: ='Lớp 3 - Công việc chính'!X16 -> Đang thực hiện | AD26: ='Lớp 3 - Công việc chính'!AC16 -> 0 | AE26: ='Lớp 3 - Công việc chính'!AA16 -> 46337 | AF26: ='Lớp 3 - Công việc chính'!AD16 -> 77 | AG26: ='Lớp 3 - Công việc chính'!AE16 -> 620 | AH26: =IF(AG26="","",AG26*(1-AD26)) -> 620 | AI26: =IF(AC26="Hoàn thành","🟢 Hoàn thành",IF(AC26="Hủy","⚪ Hủy",IF(AE26="","🔵 Chưa có hạn",IF(AE26<TODAY(),"🔴 Quá hạn",IF(AE26<=TODAY()+7,"🟠 Hạn ≤7 ngày",IF(AB26="P1","🟣 P1 trọng yếu","🟢 Theo kế hoạch")))))) -> 🟣 P1 trọng yếu | AJ26: ='Lớp 3 - Công việc chính'!AH16 -> Theo dõi tải tại Lớp 4 | AK26: =IFERROR(__xludf.DUMMYFUNCTION("""COMPUTED_VALUE"""),"Ms Trang") -> Ms Trang | AL26: =IF(AK26="","",COUNTIF($Z$24:$Z$700,AK26)) -> 32 | AM26: =IF(AK26="","",SUMIF($Z$24:$Z$700,AK26,$BI$24:$BI$700)) -> 0 | AN26: =IF(AK26="","",AM26+ROW()/1000000) -> 2.6e-05 | AS26: =IF(X26="","",TEXT(COUNTIF($X$24:X26,"<>"),"00")) -> 03 | AT26: =IF(W26=3,TRIM(SUBSTITUTE(V26,"◆","")),"") -> KHKD 2027& HT lập KH theo tham số KD (bán tự động) | AU26: =IF(W26=4,TRIM(SUBSTITUTE(V26,"├─","")),"") | AV26: =IF(W26=5,TRIM(SUBSTITUTE(V26,"├─","")),"") | AW26: =IF(W26=6,TRIM(SUBSTITUTE(SUBSTITUTE(V26,"└─",""),"├─","")),"") | AX26: =Z26 -> Em Đại | AY26: =AA26 -> Dữ liệu điều hành | AZ26: =AB26 -> P1 | BA26: =AC26 -> Đang thực hiện | BB26: =AD26 -> 0 | BC26: =AE26 -> 46337 | BD26: =AF26 -> 77 | BE26: =AG26 -> 620 | ... BH26: =AJ26 -> Theo dõi tải tại Lớp 4 | BI26: {=IF($X26="","",SWITCH($W26,3,IFERROR(INDEX('Lớp 3 - Công việc chính'!$AF$14:$AF$73,MATCH($X26,'Lớp 3 - Công việc chính'!$I$14:$I$73,0)),""),4,IFERROR(INDEX('Lớp 4 - Danh mục'!$AI$14:$AI$132,MATCH($X26,'Lớp 4 - Danh mục'!$I$14:$I$132,0)),""),5,IFERROR(INDEX('Lớp 5 - Phân công'!$AJ$14:$AJ$262,MATCH($X26,'Lớp 5 - Phân công'!$I$14:$I$262,0)),""),6,IFERROR(INDEX('Lớp 6 - Chi tiết'!$AM$14:$AM$267,MATCH($X26,'Lớp 6 - Chi tiết'!$I$14:$I$267,0)),""),""))} | BJ26: {=IF($X26="","",SWITCH($W26,3,IFERROR(INDEX('Lớp 3 - Công việc chính'!$AR$14:$AR$73,MATCH($X26,'Lớp 3 - Công việc chính'!$I$14:$I$73,0)),""),4,IFERROR(INDEX('Lớp 4 - Danh mục'!$AU$14:$AU$132,MATCH($X26,'Lớp 4 - Danh mục'!$I$14:$I$132,0)),""),5,IFERROR(INDEX('Lớp 5 - Phân công'!$AV$14:$AV$262,MATCH($X26,'Lớp 5 - Phân công'!$I$14:$I$262,0)),""),6,IFERROR(INDEX('Lớp 6 - Chi tiết'!$AY$14:$AY$267,MATCH($X26,'Lớp 6 - Chi tiết'!$I$14:$I$267,0)),""),""))} -> Theo dõi phân bổ tại Lớp 4
A27: =IF($T27="","",LET(p,$T27,m,MATCH(p,$AS$24:$AS$700,0),lvl,INDEX($W$24:$W$700,m),SWITCH(lvl,3,"▓▓ L3 "&p&" "&UPPER(IF(INDEX($AT$24:$AT$700,m)="","⚠ CHƯA NHẬP TÊN",INDEX($AT$24:$AT$700,m))),4," ├─ ▓ L4 "&p&" "&IF(INDEX($AU$24:$AU$700,m)="","⚠ Chưa nhập tên",INDEX($AU$24:$AU$700,m)),5," ├── ▒ L5 "&p&" "&IF(INDEX($AV$24:$AV$700,m)="","⚠ Chưa nhập tên công việc",INDEX($AV$24:$AV$700,m)),6," └─── ░ L6 "&p&" "&IF(INDEX($AW$24:$AW$700,m)="","⚠ Chưa nhập tên chi tiết",INDEX($AW$24:$AW$700,m)),""))) -> ├── ▒ L5 03.01.01 Liệt kê & giải quyết vấn đề còn tồn tại công thức 2025 (CK/TK/phân biệt NPP) GT | B27: =IF($T27="","",INDEX($AX$24:$AX$700,MATCH($T27,$AS$24:$AS$700,0))) -> GĐ BOC | C27: =IF($T27="","",INDEX($AY$24:$AY$700,MATCH($T27,$AS$24:$AS$700,0))) -> Dữ liệu điều hành | D27: =IF($T27="","",INDEX($AZ$24:$AZ$700,MATCH($T27,$AS$24:$AS$700,0))) -> P1 | E27: =IF($T27="","",INDEX($BA$24:$BA$700,MATCH($T27,$AS$24:$AS$700,0))) -> Chưa bắt đầu | F27: =IF($T27="","",INDEX($BB$24:$BB$700,MATCH($T27,$AS$24:$AS$700,0))) -> 0 | G27: =IF($T27="","",INDEX($BC$24:$BC$700,MATCH($T27,$AS$24:$AS$700,0))) -> 46249 | H27: =IF($T27="","",INDEX($BD$24:$BD$700,MATCH($T27,$AS$24:$AS$700,0))) -> 4 | I27: =IF($T27="","",INDEX($BF$24:$BF$700,MATCH($T27,$AS$24:$AS$700,0))) -> 16 | J27: =IF($T27="","",INDEX($BG$24:$BG$700,MATCH($T27,$AS$24:$AS$700,0))) -> 🟠 Hạn ≤7 ngày | K27: =IF($T27="","",INDEX($BH$24:$BH$700,MATCH($T27,$AS$24:$AS$700,0))) -> Bình thường – tổng 1.6/8.0 giờ/ngày | L27: {=IF($T27="","",LET(m,MATCH($T27,$AS$24:$AS$700,0),lvl,INDEX($W$24:$W$700,m),id,INDEX($X$24:$X$700,m),SWITCH(lvl,3,"Lớp 3 - Công việc chính!A"&MATCH(id,'Lớp 3 - Công việc chính'!$I$1:$I$73,0),4,"Lớp 4 - Danh mục!A"&MATCH(id,'Lớp 4 - Danh mục'!$I$1:$I$132,0),5,"Lớp 5 - Phân công!A"&MATCH(id,'Lớp 5 - Phân công'!$I$1:$I$262,0),6,"Lớp 6 - Chi tiết!A"&MATCH(id,'Lớp 6 - Chi tiết'!$I$1:$I$267,0))))} -> Lớp 5 - Phân công!A14 | M27: =IF($T27="","",INDEX($BI$24:$BI$700,MATCH($T27,$AS$24:$AS$700,0))) -> 1.6 | N27: =IF($T27="","",INDEX($BJ$24:$BJ$700,MATCH($T27,$AS$24:$AS$700,0))) -> Thiếu 12.0 giờ/tuần | T27: =IFERROR(__xludf.DUMMYFUNCTION("""COMPUTED_VALUE"""),"03.01.01") -> 03.01.01 | U27: =IF('Lớp 3 - Công việc chính'!I17="","",'Lớp 3 - Công việc chính'!I17) -> HHL3RD01 | V27: =IF('Lớp 3 - Công việc chính'!I17="","","◆ "&'Lớp 3 - Công việc chính'!M17) -> ◆ KH sản phẩm 2027-2030 | W27: =IF('Lớp 3 - Công việc chính'!I17="","",3) -> 3 | X27: ='Lớp 3 - Công việc chính'!I17 -> HHL3RD01 | Y27: =IF(X27="","","") | Z27: ='Lớp 3 - Công việc chính'!V17 -> Ms Trang | AA27: ='Lớp 3 - Công việc chính'!W17 -> R&D | AB27: ='Lớp 3 - Công việc chính'!Y17 -> P1 | AC27: ='Lớp 3 - Công việc chính'!X17 -> Đang thực hiện | AD27: ='Lớp 3 - Công việc chính'!AC17 -> 0 | AE27: ='Lớp 3 - Công việc chính'!AA17 -> 46305 | AF27: ='Lớp 3 - Công việc chính'!AD17 -> 50 | AG27: ='Lớp 3 - Công việc chính'!AE17 | AH27: =IF(AG27="","",AG27*(1-AD27)) | AI27: =IF(AC27="Hoàn thành","🟢 Hoàn thành",IF(AC27="Hủy","⚪ Hủy",IF(AE27="","🔵 Chưa có hạn",IF(AE27<TODAY(),"🔴 Quá hạn",IF(AE27<=TODAY()+7,"🟠 Hạn ≤7 ngày",IF(AB27="P1","🟣 P1 trọng yếu","🟢 Theo kế hoạch")))))) -> 🟣 P1 trọng yếu | AJ27: ='Lớp 3 - Công việc chính'!AH17 -> Theo dõi tải tại Lớp 4 | AK27: =IFERROR(__xludf.DUMMYFUNCTION("""COMPUTED_VALUE"""),"Team PTSP") -> Team PTSP | AL27: =IF(AK27="","",COUNTIF($Z$24:$Z$700,AK27)) -> 2 | AM27: =IF(AK27="","",SUMIF($Z$24:$Z$700,AK27,$BI$24:$BI$700)) -> 0 | AN27: =IF(AK27="","",AM27+ROW()/1000000) -> 2.7e-05 | AS27: =IF(X27="","",TEXT(COUNTIF($X$24:X27,"<>"),"00")) -> 04 | AT27: =IF(W27=3,TRIM(SUBSTITUTE(V27,"◆","")),"") -> KH sản phẩm 2027-2030 | AU27: =IF(W27=4,TRIM(SUBSTITUTE(V27,"├─","")),"") | AV27: =IF(W27=5,TRIM(SUBSTITUTE(V27,"├─","")),"") | AW27: =IF(W27=6,TRIM(SUBSTITUTE(SUBSTITUTE(V27,"└─",""),"├─","")),"") | AX27: =Z27 -> Ms Trang | AY27: =AA27 -> R&D | AZ27: =AB27 -> P1 | BA27: =AC27 -> Đang thực hiện | BB27: =AD27 -> 0 | BC27: =AE27 -> 46305 | BD27: =AF27 -> 50 | BE27: =AG27 | ... BH27: =AJ27 -> Theo dõi tải tại Lớp 4 | BI27: {=IF($X27="","",SWITCH($W27,3,IFERROR(INDEX('Lớp 3 - Công việc chính'!$AF$14:$AF$73,MATCH($X27,'Lớp 3 - Công việc chính'!$I$14:$I$73,0)),""),4,IFERROR(INDEX('Lớp 4 - Danh mục'!$AI$14:$AI$132,MATCH($X27,'Lớp 4 - Danh mục'!$I$14:$I$132,0)),""),5,IFERROR(INDEX('Lớp 5 - Phân công'!$AJ$14:$AJ$262,MATCH($X27,'Lớp 5 - Phân công'!$I$14:$I$262,0)),""),6,IFERROR(INDEX('Lớp 6 - Chi tiết'!$AM$14:$AM$267,MATCH($X27,'Lớp 6 - Chi tiết'!$I$14:$I$267,0)),""),""))} | BJ27: {=IF($X27="","",SWITCH($W27,3,IFERROR(INDEX('Lớp 3 - Công việc chính'!$AR$14:$AR$73,MATCH($X27,'Lớp 3 - Công việc chính'!$I$14:$I$73,0)),""),4,IFERROR(INDEX('Lớp 4 - Danh mục'!$AU$14:$AU$132,MATCH($X27,'Lớp 4 - Danh mục'!$I$14:$I$132,0)),""),5,IFERROR(INDEX('Lớp 5 - Phân công'!$AV$14:$AV$262,MATCH($X27,'Lớp 5 - Phân công'!$I$14:$I$262,0)),""),6,IFERROR(INDEX('Lớp 6 - Chi tiết'!$AY$14:$AY$267,MATCH($X27,'Lớp 6 - Chi tiết'!$I$14:$I$267,0)),""),""))} -> Theo dõi phân bổ tại Lớp 4
